<sdf version='1.6'>
  <world name='default'>
    <light name='sun' type='directional'>
      <cast_shadows>1</cast_shadows>
      <pose frame=''>0 0 10 0 -0 0</pose>
      <diffuse>0.8 0.8 0.8 1</diffuse>
      <specular>0.2 0.2 0.2 1</specular>
      <attenuation>
        <range>1000</range>
        <constant>0.9</constant>
        <linear>0.01</linear>
        <quadratic>0.001</quadratic>
      </attenuation>
      <direction>-0.5 0.1 -0.9</direction>
    </light>
    <model name='ground_plane'>
      <static>1</static>
      <link name='link'>
        <collision name='collision'>
          <geometry>
            <plane>
              <normal>0 0 1</normal>
              <size>100 100</size>
            </plane>
          </geometry>
          <surface>
            <contact>
              <collide_bitmask>65535</collide_bitmask>
              <ode/>
            </contact>
            <friction>
              <ode>
                <mu>100</mu>
                <mu2>50</mu2>
              </ode>
              <torsional>
                <ode/>
              </torsional>
            </friction>
            <bounce/>
          </surface>
          <max_contacts>10</max_contacts>
        </collision>
        <visual name='visual'>
          <cast_shadows>0</cast_shadows>
          <geometry>
            <plane>
              <normal>0 0 1</normal>
              <size>100 100</size>
            </plane>
          </geometry>
          <material>
            <script>
              <uri>file://media/materials/scripts/gazebo.material</uri>
              <name>Gazebo/Grey</name>
            </script>
          </material>
        </visual>
        <self_collide>0</self_collide>
        <enable_wind>0</enable_wind>
        <kinematic>0</kinematic>
      </link>
    </model>
    <gravity>0 0 -9.8</gravity>
    <magnetic_field>6e-06 2.3e-05 -4.2e-05</magnetic_field>
    <atmosphere type='adiabatic'/>
    <physics name='default_physics' default='0' type='ode'>
      <max_step_size>0.001</max_step_size>
      <real_time_factor>1</real_time_factor>
      <real_time_update_rate>1000</real_time_update_rate>
    </physics>
    <scene>
      <ambient>0.4 0.4 0.4 1</ambient>
      <background>0.7 0.7 0.7 1</background>
      <shadows>1</shadows>
    </scene>
    <audio>
      <device>default</device>
    </audio>
    <wind/>
    <spherical_coordinates>
      <surface_model>EARTH_WGS84</surface_model>
      <latitude_deg>0</latitude_deg>
      <longitude_deg>0</longitude_deg>
      <elevation>0</elevation>
      <heading_deg>0</heading_deg>
    </spherical_coordinates>
    <model name='pan_tilt'>
      <link name='base_link'>
        <pose frame=''>0 0 0 0 -0 0</pose>
        <inertial>
          <pose frame=''>0 0 0 0 -0 0</pose>
          <mass>10</mass>
          <inertia>
            <ixx>0.40075</ixx>
            <ixy>0</ixy>
            <ixz>0</ixz>
            <iyy>0.40075</iyy>
            <iyz>0</iyz>
            <izz>0.8</izz>
          </inertia>
        </inertial>
        <collision name='base_link_collision'>
          <pose frame=''>0 0 0.3 0 -0 0</pose>
          <geometry>
            <cylinder>
              <length>0.03</length>
              <radius>0.4</radius>
            </cylinder>
          </geometry>
          <max_contacts>10</max_contacts>
          <surface>
            <contact>
              <ode/>
            </contact>
            <bounce/>
            <friction>
              <torsional>
                <ode/>
              </torsional>
              <ode/>
            </friction>
          </surface>
        </collision>
        <visual name='base_link_visual'>
          <pose frame=''>0 0 0.3 0 -0 0</pose>
          <geometry>
            <cylinder>
              <length>0.03</length>
              <radius>0.4</radius>
            </cylinder>
          </geometry>
        </visual>
        <self_collide>0</self_collide>
        <enable_wind>0</enable_wind>
        <kinematic>0</kinematic>
      </link>
      <joint name='world_joint' type='fixed'>
        <child>base_link</child>
        <parent>world</parent>
      </joint>
      <link name='pan_link'>
        <pose frame=''>0 0 0.315 0 -0 0</pose>
        <inertial>
          <pose frame=''>0 0 0 0 -0 0</pose>
          <mass>5</mass>
          <inertia>
            <ixx>3.75</ixx>
            <ixy>0</ixy>
            <ixz>0</ixz>
            <iyy>3.75</iyy>
            <iyz>0</iyz>
            <izz>0.04</izz>
          </inertia>
        </inertial>
        <collision name='pan_link_collision'>
          <pose frame=''>0 0 0.75 0 -0 0</pose>
          <geometry>
            <cylinder>
              <length>1.5</length>
              <radius>0.06</radius>
            </cylinder>
          </geometry>
          <max_contacts>10</max_contacts>
          <surface>
            <contact>
              <ode/>
            </contact>
            <bounce/>
            <friction>
              <torsional>
                <ode/>
              </torsional>
              <ode/>
            </friction>
          </surface>
        </collision>
        <visual name='pan_link_visual'>
          <pose frame=''>0 0 0.75 0 -0 0</pose>
          <geometry>
            <cylinder>
              <length>1.5</length>
              <radius>0.04</radius>
            </cylinder>
          </geometry>
        </visual>
        <self_collide>0</self_collide>
        <enable_wind>0</enable_wind>
        <kinematic>0</kinematic>
      </link>
      <joint name='pan_joint' type='revolute'>
        <child>pan_link</child>
        <parent>base_link</parent>
        <axis>
          <xyz>0 0 1</xyz>
          <limit>
            <lower>-1e+06</lower>
            <upper>1e+06</upper>
            <effort>300</effort>
            <velocity>0.1</velocity>
          </limit>
          <dynamics>
            <damping>50</damping>
            <friction>1</friction>
            <spring_reference>0</spring_reference>
            <spring_stiffness>0</spring_stiffness>
          </dynamics>
          <use_parent_model_frame>1</use_parent_model_frame>
        </axis>
      </joint>
      <link name='tilt_link'>
        <pose frame=''>0 0.09 1.815 0 -0 0</pose>
        <inertial>
          <pose frame=''>0.001267 0.002281 0.022301 0 -0 0</pose>
          <mass>5.564</mass>
          <inertia>
            <ixx>0.294666</ixx>
            <ixy>-0.000142548</ixy>
            <ixz>-0.00139378</ixz>
            <iyy>0.291109</iyy>
            <iyz>-0.00250881</iyz>
            <izz>0.404217</izz>
          </inertia>
        </inertial>
        <collision name='tilt_link_collision'>
          <pose frame=''>0 0 0.1 0 -0 0</pose>
          <geometry>
            <cylinder>
              <length>0.2</length>
              <radius>0.24</radius>
            </cylinder>
          </geometry>
          <max_contacts>10</max_contacts>
          <surface>
            <contact>
              <ode/>
            </contact>
            <bounce/>
            <friction>
              <torsional>
                <ode/>
              </torsional>
              <ode/>
            </friction>
          </surface>
        </collision>
        <collision name='tilt_link_fixed_joint_lump__camera_link_collision_1'>
          <pose frame=''>0.0125 0.04 0.219999 3.14159 -1.57079 -3e-06</pose>
          <geometry>
            <box>
              <size>0.02505 0.09 0.025</size>
            </box>
          </geometry>
          <surface>
            <contact>
              <ode/>
            </contact>
            <friction>
              <ode/>
              <torsional>
                <ode/>
              </torsional>
            </friction>
            <bounce/>
          </surface>
          <max_contacts>10</max_contacts>
        </collision>
        <visual name='tilt_link_visual'>
          <pose frame=''>0 0 0.1 0 -0 0</pose>
          <geometry>
            <cylinder>
              <length>0.2</length>
              <radius>0.04</radius>
            </cylinder>
          </geometry>
        </visual>
        <visual name='tilt_link_fixed_joint_lump__camera_link_visual_1'>
          <pose frame=''>0.012501 0.005 0.234899 -0.000193 -9.6e-05 -1.5708</pose>
          <geometry>
            <mesh>
              <scale>1 1 1</scale>
              <uri>model://intel_realsense_d435/meshes/d435.dae</uri>
            </mesh>
          </geometry>
          <material>
            <script>
              <uri>__default__</uri>
              <name>__default__</name>
            </script>
          </material>
        </visual>
        <gravity>1</gravity>
        <velocity_decay/>
        <sensor name='cameracolor' type='camera'>
          <camera name='camera'>
            <horizontal_fov>1.21126</horizontal_fov>
            <image>
              <width>640</width>
              <height>480</height>
              <format>RGB_INT8</format>
            </image>
            <clip>
              <near>0.1</near>
              <far>100</far>
            </clip>
            <noise>
              <type>gaussian</type>
              <mean>0</mean>
              <stddev>0.007</stddev>
            </noise>
          </camera>
          <always_on>1</always_on>
          <update_rate>30</update_rate>
          <visualize>1</visualize>
          <pose frame=''>0.0125 0.0225 0.219999 3.14159 -1.57079 -3e-06</pose>
        </sensor>
        <sensor name='cameraired1' type='camera'>
          <camera name='camera'>
            <horizontal_fov>1.48702</horizontal_fov>
            <image>
              <width>1280</width>
              <height>720</height>
              <format>L_INT8</format>
            </image>
            <clip>
              <near>0.1</near>
              <far>100</far>
            </clip>
            <noise>
              <type>gaussian</type>
              <mean>0</mean>
              <stddev>0.05</stddev>
            </noise>
          </camera>
          <always_on>1</always_on>
          <update_rate>90</update_rate>
          <visualize>1</visualize>
          <pose frame=''>0.0125 0.0225 0.219999 3.14159 -1.57079 -3e-06</pose>
        </sensor>
        <sensor name='cameraired2' type='camera'>
          <camera name='camera'>
            <horizontal_fov>1.48702</horizontal_fov>
            <image>
              <width>1280</width>
              <height>720</height>
              <format>L_INT8</format>
            </image>
            <clip>
              <near>0.1</near>
              <far>100</far>
            </clip>
            <noise>
              <type>gaussian</type>
              <mean>0</mean>
              <stddev>0.05</stddev>
            </noise>
          </camera>
          <always_on>1</always_on>
          <update_rate>90</update_rate>
          <visualize>1</visualize>
          <pose frame=''>0.0125 0.0225 0.219999 3.14159 -1.57079 -3e-06</pose>
        </sensor>
        <sensor name='cameradepth' type='depth'>
          <camera name='camera'>
            <horizontal_fov>1.48702</horizontal_fov>
            <image>
              <width>640</width>
              <height>480</height>
            </image>
            <clip>
              <near>0.1</near>
              <far>100</far>
            </clip>
            <noise>
              <type>gaussian</type>
              <mean>0</mean>
              <stddev>0.1</stddev>
            </noise>
          </camera>
          <always_on>1</always_on>
          <update_rate>90</update_rate>
          <visualize>0</visualize>
          <pose frame=''>0.0125 0.0225 0.219999 3.14159 -1.57079 -3e-06</pose>
        </sensor>
        <self_collide>0</self_collide>
        <enable_wind>0</enable_wind>
        <kinematic>0</kinematic>
      </link>
      <joint name='tilt_joint' type='revolute'>
        <child>tilt_link</child>
        <parent>pan_link</parent>
        <axis>
          <xyz>0 1 0</xyz>
          <limit>
            <lower>-2</lower>
            <upper>2</upper>
            <effort>300</effort>
            <velocity>0.5</velocity>
          </limit>
          <dynamics>
            <damping>50</damping>
            <friction>1</friction>
            <spring_reference>0</spring_reference>
            <spring_stiffness>0</spring_stiffness>
          </dynamics>
          <use_parent_model_frame>1</use_parent_model_frame>
        </axis>
      </joint>
      <static>0</static>
      <plugin name='camera' filename='librealsense_gazebo_plugin.so'>
        <prefix>camera</prefix>
        <depthUpdateRate>30.0</depthUpdateRate>
        <colorUpdateRate>30.0</colorUpdateRate>
        <infraredUpdateRate>30.0</infraredUpdateRate>
        <depthTopicName>depth/image_raw</depthTopicName>
        <depthCameraInfoTopicName>depth/camera_info</depthCameraInfoTopicName>
        <colorTopicName>color/image_raw</colorTopicName>
        <colorCameraInfoTopicName>color/camera_info</colorCameraInfoTopicName>
        <infrared1TopicName>infra1/image_raw</infrared1TopicName>
        <infrared1CameraInfoTopicName>infra1/camera_info</infrared1CameraInfoTopicName>
        <infrared2TopicName>infra2/image_raw</infrared2TopicName>
        <infrared2CameraInfoTopicName>infra2/camera_info</infrared2CameraInfoTopicName>
        <colorOpticalframeName>camera_color_optical_frame</colorOpticalframeName>
        <depthOpticalframeName>camera_depth_optical_frame</depthOpticalframeName>
        <infrared1OpticalframeName>camera_left_ir_optical_frame</infrared1OpticalframeName>
        <infrared2OpticalframeName>camera_right_ir_optical_frame</infrared2OpticalframeName>
        <rangeMinDepth>0.2</rangeMinDepth>
        <rangeMaxDepth>10.0</rangeMaxDepth>
        <pointCloud>1</pointCloud>
        <pointCloudTopicName>depth/color/points</pointCloudTopicName>
        <pointCloudCutoff>0.25</pointCloudCutoff>
        <pointCloudCutoffMax>9.0</pointCloudCutoffMax>
        <robotNamespace>/</robotNamespace>
      </plugin>
      <plugin name='my_robot' filename='libmyrobot_plugin.so'>
        <robotNamespace>/</robotNamespace>
      </plugin>
      <pose frame=''>0 0 0 0 -0 0</pose>
    </model>
    <model name='coke_can'>
      <link name='link'>
        <inertial>
          <pose frame=''>0 0 0.06 0 -0 0</pose>
          <mass>0.39</mass>
          <inertia>
            <ixx>0.00055575</ixx>
            <ixy>0</ixy>
            <ixz>0</ixz>
            <iyy>0.00055575</iyy>
            <iyz>0</iyz>
            <izz>0.0001755</izz>
          </inertia>
        </inertial>
        <collision name='collision'>
          <pose frame=''>0.003937 0.004724 -0.18 0 -0 0</pose>
          <geometry>
            <mesh>
              <uri>model://coke_can/meshes/coke_can.dae</uri>
            </mesh>
          </geometry>
          <surface>
            <friction>
              <ode>
                <mu>1</mu>
                <mu2>1</mu2>
              </ode>
              <torsional>
                <ode/>
              </torsional>
            </friction>
            <contact>
              <ode>
                <kp>1e+07</kp>
                <kd>1</kd>
                <min_depth>0.001</min_depth>
                <max_vel>0.1</max_vel>
              </ode>
            </contact>
            <bounce/>
          </surface>
          <max_contacts>10</max_contacts>
        </collision>
        <visual name='visual'>
          <pose frame=''>0.003937 0.004724 -0.18 0 -0 0</pose>
          <geometry>
            <mesh>
              <uri>model://coke_can/meshes/coke_can.dae</uri>
            </mesh>
          </geometry>
        </visual>
        <self_collide>0</self_collide>
        <enable_wind>0</enable_wind>
        <kinematic>0</kinematic>
      </link>
      <pose frame=''>-5.17991 2.34654 0 0 -0 0</pose>
    </model>
    <model name='cafe_table'>
      <static>1</static>
      <link name='link'>
        <collision name='surface'>
          <pose frame=''>0 0 0.755 0 -0 0</pose>
          <geometry>
            <box>
              <size>0.913 0.913 0.04</size>
            </box>
          </geometry>
          <max_contacts>10</max_contacts>
          <surface>
            <contact>
              <ode/>
            </contact>
            <bounce/>
            <friction>
              <torsional>
                <ode/>
              </torsional>
              <ode/>
            </friction>
          </surface>
        </collision>
        <collision name='column'>
          <pose frame=''>0 0 0.37 0 -0 0</pose>
          <geometry>
            <box>
              <size>0.042 0.042 0.74</size>
            </box>
          </geometry>
          <max_contacts>10</max_contacts>
          <surface>
            <contact>
              <ode/>
            </contact>
            <bounce/>
            <friction>
              <torsional>
                <ode/>
              </torsional>
              <ode/>
            </friction>
          </surface>
        </collision>
        <collision name='base'>
          <pose frame=''>0 0 0.02 0 -0 0</pose>
          <geometry>
            <box>
              <size>0.56 0.56 0.04</size>
            </box>
          </geometry>
          <max_contacts>10</max_contacts>
          <surface>
            <contact>
              <ode/>
            </contact>
            <bounce/>
            <friction>
              <torsional>
                <ode/>
              </torsional>
              <ode/>
            </friction>
          </surface>
        </collision>
        <visual name='visual'>
          <geometry>
            <mesh>
              <uri>model://cafe_table/meshes/cafe_table.dae</uri>
            </mesh>
          </geometry>
        </visual>
        <self_collide>0</self_collide>
        <enable_wind>0</enable_wind>
        <kinematic>0</kinematic>
      </link>
      <pose frame=''>1.25656 0.069542 0 0 -0 0</pose>
    </model>
    <model name='cafe_table_0'>
      <static>1</static>
      <link name='link'>
        <collision name='surface'>
          <pose frame=''>0 0 0.755 0 -0 0</pose>
          <geometry>
            <box>
              <size>0.913 0.913 0.04</size>
            </box>
          </geometry>
          <max_contacts>10</max_contacts>
          <surface>
            <contact>
              <ode/>
            </contact>
            <bounce/>
            <friction>
              <torsional>
                <ode/>
              </torsional>
              <ode/>
            </friction>
          </surface>
        </collision>
        <collision name='column'>
          <pose frame=''>0 0 0.37 0 -0 0</pose>
          <geometry>
            <box>
              <size>0.042 0.042 0.74</size>
            </box>
          </geometry>
          <max_contacts>10</max_contacts>
          <surface>
            <contact>
              <ode/>
            </contact>
            <bounce/>
            <friction>
              <torsional>
                <ode/>
              </torsional>
              <ode/>
            </friction>
          </surface>
        </collision>
        <collision name='base'>
          <pose frame=''>0 0 0.02 0 -0 0</pose>
          <geometry>
            <box>
              <size>0.56 0.56 0.04</size>
            </box>
          </geometry>
          <max_contacts>10</max_contacts>
          <surface>
            <contact>
              <ode/>
            </contact>
            <bounce/>
            <friction>
              <torsional>
                <ode/>
              </torsional>
              <ode/>
            </friction>
          </surface>
        </collision>
        <visual name='visual'>
          <geometry>
            <mesh>
              <uri>model://cafe_table/meshes/cafe_table.dae</uri>
            </mesh>
          </geometry>
        </visual>
        <self_collide>0</self_collide>
        <enable_wind>0</enable_wind>
        <kinematic>0</kinematic>
      </link>
      <pose frame=''>1.25732 -0.863445 0 0 -0 0</pose>
    </model>
    <model name='cafe_table_1'>
      <static>1</static>
      <link name='link'>
        <collision name='surface'>
          <pose frame=''>0 0 0.755 0 -0 0</pose>
          <geometry>
            <box>
              <size>0.913 0.913 0.04</size>
            </box>
          </geometry>
          <max_contacts>10</max_contacts>
          <surface>
            <contact>
              <ode/>
            </contact>
            <bounce/>
            <friction>
              <torsional>
                <ode/>
              </torsional>
              <ode/>
            </friction>
          </surface>
        </collision>
        <collision name='column'>
          <pose frame=''>0 0 0.37 0 -0 0</pose>
          <geometry>
            <box>
              <size>0.042 0.042 0.74</size>
            </box>
          </geometry>
          <max_contacts>10</max_contacts>
          <surface>
            <contact>
              <ode/>
            </contact>
            <bounce/>
            <friction>
              <torsional>
                <ode/>
              </torsional>
              <ode/>
            </friction>
          </surface>
        </collision>
        <collision name='base'>
          <pose frame=''>0 0 0.02 0 -0 0</pose>
          <geometry>
            <box>
              <size>0.56 0.56 0.04</size>
            </box>
          </geometry>
          <max_contacts>10</max_contacts>
          <surface>
            <contact>
              <ode/>
            </contact>
            <bounce/>
            <friction>
              <torsional>
                <ode/>
              </torsional>
              <ode/>
            </friction>
          </surface>
        </collision>
        <visual name='visual'>
          <geometry>
            <mesh>
              <uri>model://cafe_table/meshes/cafe_table.dae</uri>
            </mesh>
          </geometry>
        </visual>
        <self_collide>0</self_collide>
        <enable_wind>0</enable_wind>
        <kinematic>0</kinematic>
      </link>
      <pose frame=''>1.26085 0.991577 0 0 -0 0</pose>
    </model>
    <model name='beer'>
      <link name='link'>
        <pose frame=''>0 0 0.115 0 -0 0</pose>
        <inertial>
          <mass>0.39</mass>
          <inertia>
            <ixx>0.00058</ixx>
            <ixy>0</ixy>
            <ixz>0</ixz>
            <iyy>0.00058</iyy>
            <iyz>0</iyz>
            <izz>0.00019</izz>
          </inertia>
        </inertial>
        <collision name='collision'>
          <geometry>
            <cylinder>
              <radius>0.055</radius>
              <length>0.23</length>
            </cylinder>
          </geometry>
          <max_contacts>10</max_contacts>
          <surface>
            <contact>
              <ode/>
            </contact>
            <bounce/>
            <friction>
              <torsional>
                <ode/>
              </torsional>
              <ode/>
            </friction>
          </surface>
        </collision>
        <visual name='visual'>
          <geometry>
            <cylinder>
              <radius>0.055</radius>
              <length>0.23</length>
            </cylinder>
          </geometry>
          <material>
            <script>
              <uri>model://beer/materials/scripts</uri>
              <uri>model://beer/materials/textures</uri>
              <name>Beer/Diffuse</name>
            </script>
          </material>
        </visual>
        <self_collide>0</self_collide>
        <enable_wind>0</enable_wind>
        <kinematic>0</kinematic>
      </link>
      <pose frame=''>1.60442 1.05924 0 0 -0 0</pose>
    </model>
    <model name='mpl_right_arm'>
      <link name='shoulder'>
        <pose frame=''>0 0 0.093285 0 0 -0.011537</pose>
        <inertial>
          <pose frame=''>0.000536 0.002002 0.03328 0 -0 0</pose>
          <mass>0.0363799</mass>
          <inertia>
            <ixx>3.73005e-05</ixx>
            <ixy>5.68571e-07</ixy>
            <ixz>-7.59543e-07</ixz>
            <iyy>2.60558e-05</iyy>
            <iyz>-9.15512e-07</iyz>
            <izz>3.86186e-05</izz>
          </inertia>
        </inertial>
        <collision name='collision'>
          <pose frame=''>0 0 0.0345 0 -0 0</pose>
          <geometry>
            <sphere>
              <radius>0.03495</radius>
            </sphere>
          </geometry>
          <surface>
            <contact>
              <ode>
                <kp>100000</kp>
                <kd>10</kd>
                <max_vel>0.1</max_vel>
                <min_depth>0.0015</min_depth>
              </ode>
            </contact>
            <bounce/>
            <friction>
              <torsional>
                <ode/>
              </torsional>
              <ode/>
            </friction>
          </surface>
          <max_contacts>10</max_contacts>
        </collision>
        <collision name='collision_1'>
          <pose frame=''>0 0 0.01892 0 -0 0</pose>
          <geometry>
            <cylinder>
              <radius>0.038</radius>
              <length>0.03784</length>
            </cylinder>
          </geometry>
          <surface>
            <contact>
              <ode>
                <kp>100000</kp>
                <kd>10</kd>
                <max_vel>0.1</max_vel>
                <min_depth>0.0015</min_depth>
              </ode>
            </contact>
            <bounce/>
            <friction>
              <torsional>
                <ode/>
              </torsional>
              <ode/>
            </friction>
          </surface>
          <max_contacts>10</max_contacts>
        </collision>
        <visual name='visual'>
          <geometry>
            <mesh>
              <uri>model://mpl_right_arm/meshes/shoulder.stl</uri>
            </mesh>
          </geometry>
          <material>
            <script>
              <name>Gazebo/FlatBlack</name>
              <uri>__default__</uri>
            </script>
          </material>
        </visual>
        <self_collide>0</self_collide>
        <enable_wind>0</enable_wind>
        <kinematic>0</kinematic>
      </link>
      <link name='humerus'>
        <pose frame=''>0.001643 -1.9e-05 0.12058 0 0 -0.011537</pose>
        <inertial>
          <pose frame=''>-0.00523 -0.083481 0.010842 0 -0 0</pose>
          <mass>0.0857896</mass>
          <inertia>
            <ixx>0.000259543</ixx>
            <ixy>-4.20463e-06</ixy>
            <ixz>9.18286e-07</ixz>
            <iyy>0.000134353</iyy>
            <iyz>-1.37928e-05</iyz>
            <izz>0.000284981</izz>
          </inertia>
        </inertial>
        <collision name='collision'>
          <pose frame=''>-0.00164 -0.07024 0.01366 1.5707 -0 0</pose>
          <geometry>
            <cylinder>
              <radius>0.037035</radius>
              <length>0.15849</length>
            </cylinder>
          </geometry>
          <surface>
            <contact>
              <ode>
                <kp>100000</kp>
                <kd>10</kd>
                <max_vel>0.1</max_vel>
                <min_depth>0.0015</min_depth>
              </ode>
            </contact>
            <bounce/>
            <friction>
              <torsional>
                <ode/>
              </torsional>
              <ode/>
            </friction>
          </surface>
          <max_contacts>10</max_contacts>
        </collision>
        <visual name='visual'>
          <geometry>
            <mesh>
              <uri>model://mpl_right_arm/meshes/humerus.stl</uri>
            </mesh>
          </geometry>
          <material>
            <script>
              <name>Gazebo/FlatBlack</name>
              <uri>__default__</uri>
            </script>
          </material>
        </visual>
        <self_collide>0</self_collide>
        <enable_wind>0</enable_wind>
        <kinematic>0</kinematic>
      </link>
      <link name='elbow'>
        <pose frame=''>-0.001728 -0.150057 0.134471 0 0 -0.011537</pose>
        <inertial>
          <pose frame=''>0.001164 -0.074089 -0.007315 0 -0 0</pose>
          <mass>0.0351897</mass>
          <inertia>
            <ixx>0.000106583</ixx>
            <ixy>-5.90862e-06</ixy>
            <ixz>-2.34382e-06</ixz>
            <iyy>3.29639e-05</iyy>
            <iyz>1.56515e-05</iyz>
            <izz>0.000106705</izz>
          </inertia>
        </inertial>
        <collision name='collision'>
          <pose frame=''>0 -0.05957 0.00147 1.5707 -0 0</pose>
          <geometry>
            <cylinder>
              <radius>0.03447</radius>
              <length>0.11914</length>
            </cylinder>
          </geometry>
          <surface>
            <contact>
              <ode>
                <kp>100000</kp>
                <kd>10</kd>
                <max_vel>0.1</max_vel>
                <min_depth>0.0015</min_depth>
              </ode>
            </contact>
            <bounce/>
            <friction>
              <torsional>
                <ode/>
              </torsional>
              <ode/>
            </friction>
          </surface>
          <max_contacts>10</max_contacts>
        </collision>
        <collision name='collision_1'>
          <pose frame=''>0.00997 -0.1445 -0.0245 0 -0 0</pose>
          <geometry>
            <cylinder>
              <radius>0.036</radius>
              <length>0.018</length>
            </cylinder>
          </geometry>
          <surface>
            <contact>
              <ode>
                <kp>100000</kp>
                <kd>10</kd>
                <max_vel>0.1</max_vel>
                <min_depth>0.0015</min_depth>
              </ode>
            </contact>
            <bounce/>
            <friction>
              <torsional>
                <ode/>
              </torsional>
              <ode/>
            </friction>
          </surface>
          <max_contacts>10</max_contacts>
        </collision>
        <visual name='visual'>
          <geometry>
            <mesh>
              <uri>model://mpl_right_arm/meshes/elbow.stl</uri>
            </mesh>
          </geometry>
          <material>
            <ambient>0.2 0.2 0.2 1</ambient>
            <diffuse>0.8 0.8 0.8 1</diffuse>
            <specular>0.9 0.9 0.9 1</specular>
          </material>
        </visual>
        <self_collide>0</self_collide>
        <enable_wind>0</enable_wind>
        <kinematic>0</kinematic>
      </link>
      <link name='forearm'>
        <pose frame=''>0.006605 -0.294573 0.119123 0 0 -0.011537</pose>
        <inertial>
          <pose frame=''>-0.000589 -0.073314 0.021553 0 -0 0</pose>
          <mass>0.0997005</mass>
          <inertia>
            <ixx>0.0004998</ixx>
            <ixy>-5.83136e-06</ixy>
            <ixz>3.56083e-07</ixz>
            <iyy>0.00010215</iyy>
            <iyz>3.76069e-05</iyz>
            <izz>0.000498862</izz>
          </inertia>
        </inertial>
        <collision name='collision'>
          <pose frame=''>0 0 0.02855 0 -0 0</pose>
          <geometry>
            <cylinder>
              <radius>0.03567</radius>
              <length>0.0571</length>
            </cylinder>
          </geometry>
          <surface>
            <contact>
              <ode>
                <kp>100000</kp>
                <kd>10</kd>
                <max_vel>0.1</max_vel>
                <min_depth>0.0015</min_depth>
              </ode>
            </contact>
            <bounce/>
            <friction>
              <torsional>
                <ode/>
              </torsional>
              <ode/>
            </friction>
          </surface>
          <max_contacts>10</max_contacts>
        </collision>
        <collision name='collision_1'>
          <pose frame=''>0 -0.10745 0.016 1.5707 -0 0</pose>
          <geometry>
            <cylinder>
              <radius>0.035</radius>
              <length>0.148</length>
            </cylinder>
          </geometry>
          <surface>
            <contact>
              <ode>
                <kp>100000</kp>
                <kd>10</kd>
                <max_vel>0.1</max_vel>
                <min_depth>0.0015</min_depth>
              </ode>
            </contact>
            <bounce/>
            <friction>
              <torsional>
                <ode/>
              </torsional>
              <ode/>
            </friction>
          </surface>
          <max_contacts>10</max_contacts>
        </collision>
        <visual name='visual'>
          <geometry>
            <mesh>
              <uri>model://mpl_right_arm/meshes/forearm.stl</uri>
            </mesh>
          </geometry>
          <material>
            <script>
              <name>Gazebo/FlatBlack</name>
              <uri>__default__</uri>
            </script>
          </material>
        </visual>
        <sensor name='forearm_contact_sensor' type='contact'>
          <contact>
            <collision>collision</collision>
            <collision>collision_1</collision>
            <topic>~/forearm/contact</topic>
          </contact>
        </sensor>
        <self_collide>0</self_collide>
        <enable_wind>0</enable_wind>
        <kinematic>0</kinematic>
      </link>
      <link name='wristy'>
        <pose frame=''>0.004499 -0.479995 0.135123 0 0 -0.011537</pose>
        <inertial>
          <pose frame=''>-7.1e-05 -0.021779 -0.000286 0 -0 0</pose>
          <mass>0.0272932</mass>
          <inertia>
            <ixx>1.77029e-05</ixx>
            <ixy>7.89061e-09</ixy>
            <ixz>4.33867e-09</ixz>
            <iyy>2.46772e-05</iyy>
            <iyz>1.77331e-07</iyz>
            <izz>1.7112e-05</izz>
          </inertia>
        </inertial>
        <collision name='collision'>
          <pose frame=''>0 -0.025 0 1.5707 -0 0</pose>
          <geometry>
            <cylinder>
              <radius>0.03447</radius>
              <length>0.05</length>
            </cylinder>
          </geometry>
          <surface>
            <contact>
              <ode>
                <kp>100000</kp>
                <kd>10</kd>
                <max_vel>0.1</max_vel>
                <min_depth>0.0015</min_depth>
              </ode>
            </contact>
            <bounce/>
            <friction>
              <torsional>
                <ode/>
              </torsional>
              <ode/>
            </friction>
          </surface>
          <max_contacts>10</max_contacts>
        </collision>
        <visual name='visual'>
          <geometry>
            <mesh>
              <uri>model://mpl_right_arm/meshes/wristy.stl</uri>
            </mesh>
          </geometry>
          <material>
            <ambient>0.2 0.2 0.2 1</ambient>
            <diffuse>0.8 0.8 0.8 1</diffuse>
            <specular>0.9 0.9 0.9 1</specular>
          </material>
        </visual>
        <sensor name='wristy_contact_sensor' type='contact'>
          <contact>
            <collision>collision</collision>
            <topic>~/wristy/contact</topic>
          </contact>
        </sensor>
        <self_collide>0</self_collide>
        <enable_wind>0</enable_wind>
        <kinematic>0</kinematic>
      </link>
      <link name='wristx'>
        <pose frame=''>0.003916 -0.527636 0.137161 0 0 -0.011537</pose>
        <inertial>
          <pose frame=''>0.001392 -0.009752 -0.002527 0 -0 0</pose>
          <mass>0.010691</mass>
          <inertia>
            <ixx>3.27995e-06</ixx>
            <ixy>-1.50151e-07</ixy>
            <ixz>5.11904e-09</ixz>
            <iyy>4.22942e-06</iyy>
            <iyz>-4.20007e-08</iyz>
            <izz>5.04229e-06</izz>
          </inertia>
        </inertial>
        <collision name='collision'>
          <pose frame=''>0 0 -0.00314 0 -0 0</pose>
          <geometry>
            <cylinder>
              <radius>0.01473</radius>
              <length>0.04478</length>
            </cylinder>
          </geometry>
          <surface>
            <contact>
              <ode>
                <kp>100000</kp>
                <kd>10</kd>
                <max_vel>0.1</max_vel>
                <min_depth>0.0015</min_depth>
              </ode>
            </contact>
            <bounce/>
            <friction>
              <torsional>
                <ode/>
              </torsional>
              <ode/>
            </friction>
          </surface>
          <max_contacts>10</max_contacts>
        </collision>
        <collision name='collision_1'>
          <pose frame=''>0.0236 -0.02969 -0.0024 0 1.5707 0</pose>
          <geometry>
            <cylinder>
              <radius>0.013175</radius>
              <length>0.005</length>
            </cylinder>
          </geometry>
          <surface>
            <contact>
              <ode>
                <kp>100000</kp>
                <kd>10</kd>
                <max_vel>0.1</max_vel>
                <min_depth>0.0015</min_depth>
              </ode>
            </contact>
            <bounce/>
            <friction>
              <torsional>
                <ode/>
              </torsional>
              <ode/>
            </friction>
          </surface>
          <max_contacts>10</max_contacts>
        </collision>
        <collision name='collision_2'>
          <pose frame=''>-0.0236 -0.02969 -0.0024 0 1.5707 0</pose>
          <geometry>
            <cylinder>
              <radius>0.013175</radius>
              <length>0.005</length>
            </cylinder>
          </geometry>
          <surface>
            <contact>
              <ode>
                <kp>100000</kp>
                <kd>10</kd>
                <max_vel>0.1</max_vel>
                <min_depth>0.0015</min_depth>
              </ode>
            </contact>
            <bounce/>
            <friction>
              <torsional>
                <ode/>
              </torsional>
              <ode/>
            </friction>
          </surface>
          <max_contacts>10</max_contacts>
        </collision>
        <visual name='visual'>
          <geometry>
            <mesh>
              <uri>model://mpl_right_arm/meshes/wristx.stl</uri>
            </mesh>
          </geometry>
          <material>
            <ambient>0.2 0.2 0.2 1</ambient>
            <diffuse>0.8 0.8 0.8 1</diffuse>
            <specular>0.9 0.9 0.9 1</specular>
          </material>
        </visual>
        <sensor name='wristx_contact_sensor' type='contact'>
          <contact>
            <collision>collision</collision>
            <collision>collision_1</collision>
            <collision>collision_2</collision>
            <topic>~/wristx/contact</topic>
          </contact>
        </sensor>
        <self_collide>0</self_collide>
        <enable_wind>0</enable_wind>
        <kinematic>0</kinematic>
      </link>
      <link name='wristz'>
        <pose frame=''>0.003757 -0.557636 0.135067 0 0 -0.011537</pose>
        <inertial>
          <pose frame=''>0.003682 -0.035876 0.002659 0 -0 0</pose>
          <mass>0.125889</mass>
          <inertia>
            <ixx>8.18077e-05</ixx>
            <ixy>-9.44149e-06</ixy>
            <ixz>3.88366e-06</ixz>
            <iyy>9.81482e-05</iyy>
            <iyz>-4.84151e-08</iyz>
            <izz>0.000131783</izz>
          </inertia>
        </inertial>
        <collision name='collision'>
          <pose frame=''>0.00207 -0.00047 0.00046 1.5707 0 1.5707</pose>
          <geometry>
            <cylinder>
              <radius>0.01411</radius>
              <length>0.04482</length>
            </cylinder>
          </geometry>
          <surface>
            <contact>
              <ode>
                <kp>100000</kp>
                <kd>10</kd>
                <max_vel>0.1</max_vel>
                <min_depth>0.0015</min_depth>
              </ode>
            </contact>
            <bounce/>
            <friction>
              <torsional>
                <ode/>
              </torsional>
              <ode/>
            </friction>
          </surface>
          <max_contacts>10</max_contacts>
        </collision>
        <collision name='collision_palm'>
          <pose frame=''>0.002 -0.03739 0 0 -0 0</pose>
          <geometry>
            <box>
              <size>0.07928 0.08316 0.04402</size>
            </box>
          </geometry>
          <surface>
            <contact>
              <ode>
                <kp>100000</kp>
                <kd>100</kd>
                <max_vel>0.1</max_vel>
                <min_depth>0.0015</min_depth>
              </ode>
            </contact>
            <bounce/>
            <friction>
              <torsional>
                <ode/>
              </torsional>
              <ode/>
            </friction>
          </surface>
          <max_contacts>10</max_contacts>
        </collision>
        <visual name='visual'>
          <geometry>
            <mesh>
              <uri>model://mpl_right_arm/meshes/wristz.stl</uri>
            </mesh>
          </geometry>
          <material>
            <ambient>0.2 0.2 0.2 1</ambient>
            <diffuse>0.8 0.8 0.8 1</diffuse>
            <specular>0.9 0.9 0.9 1</specular>
          </material>
        </visual>
        <visual name='visual_palm'>
          <pose frame=''>0.025625 0 0 0 -0 0</pose>
          <geometry>
            <mesh>
              <uri>model://mpl_right_arm/meshes/palm.stl</uri>
            </mesh>
          </geometry>
          <material>
            <script>
              <name>Gazebo/FlatBlack</name>
              <uri>__default__</uri>
            </script>
          </material>
        </visual>
        <sensor name='palm_contact_sensor' type='contact'>
          <contact>
            <collision>collision_palm</collision>
            <topic>~/palm/contact</topic>
          </contact>
        </sensor>
        <self_collide>0</self_collide>
        <enable_wind>0</enable_wind>
        <kinematic>0</kinematic>
      </link>
      <link name='index0'>
        <pose frame=''>0.038485 -0.623842 0.136079 0 0.174533 -0.011537</pose>
        <inertial>
          <pose frame=''>-0.000143 -0.005485 0.000206 0 -0 0</pose>
          <mass>0.00295579</mass>
          <inertia>
            <ixx>4.22375e-07</ixx>
            <ixy>4.23313e-09</ixy>
            <ixz>5.00708e-10</ixz>
            <iyy>1.94048e-07</iyy>
            <iyz>-4.58697e-09</iyz>
            <izz>4.02188e-07</izz>
          </inertia>
        </inertial>
        <collision name='collision'>
          <pose frame=''>0 -0.01339 0 1.5707 -0 0</pose>
          <geometry>
            <cylinder>
              <length>0.028</length>
              <radius>0.01</radius>
            </cylinder>
          </geometry>
          <surface>
            <contact>
              <ode>
                <kp>100000</kp>
                <kd>10</kd>
                <max_vel>0.1</max_vel>
                <min_depth>0.0015</min_depth>
              </ode>
            </contact>
            <bounce/>
            <friction>
              <torsional>
                <ode/>
              </torsional>
              <ode/>
            </friction>
          </surface>
          <max_contacts>10</max_contacts>
        </collision>
        <visual name='visual'>
          <geometry>
            <mesh>
              <uri>model://mpl_right_arm/meshes/index0.stl</uri>
            </mesh>
          </geometry>
          <material>
            <script>
              <name>Gazebo/FlatBlack</name>
              <uri>__default__</uri>
            </script>
          </material>
        </visual>
        <sensor name='index0_contact_sensor' type='contact'>
          <contact>
            <collision>collision</collision>
            <topic>~/index0/contact</topic>
          </contact>
        </sensor>
        <self_collide>0</self_collide>
        <enable_wind>0</enable_wind>
        <kinematic>0</kinematic>
      </link>
      <link name='index1'>
        <pose frame=''>0.038339 -0.641841 0.136068 0 0.174533 -0.011537</pose>
        <inertial>
          <pose frame=''>0.000406 -0.021313 0.000656 0 -0 0</pose>
          <mass>0.00478235</mass>
          <inertia>
            <ixx>8.18593e-07</ixx>
            <ixy>-1.2874e-09</ixy>
            <ixz>1.78664e-10</ixz>
            <iyy>3.06547e-07</iyy>
            <iyz>-1.18998e-08</iyz>
            <izz>7.95406e-07</izz>
          </inertia>
        </inertial>
        <collision name='collision'>
          <pose frame=''>0 -0.02782 0 1.5707 -0 0</pose>
          <geometry>
            <cylinder>
              <radius>0.01</radius>
              <length>0.02781</length>
            </cylinder>
          </geometry>
          <surface>
            <contact>
              <ode>
                <kp>100000</kp>
                <kd>10</kd>
                <max_vel>0.1</max_vel>
                <min_depth>0.0015</min_depth>
              </ode>
            </contact>
            <bounce/>
            <friction>
              <torsional>
                <ode/>
              </torsional>
              <ode/>
            </friction>
          </surface>
          <max_contacts>10</max_contacts>
        </collision>
        <visual name='visual'>
          <geometry>
            <mesh>
              <uri>model://mpl_right_arm/meshes/index1.stl</uri>
            </mesh>
          </geometry>
          <material>
            <script>
              <name>Gazebo/FlatBlack</name>
              <uri>__default__</uri>
            </script>
          </material>
        </visual>
        <sensor name='index1_contact_sensor' type='contact'>
          <contact>
            <collision>collision</collision>
            <topic>~/index1/contact</topic>
          </contact>
        </sensor>
        <self_collide>0</self_collide>
        <enable_wind>0</enable_wind>
        <kinematic>0</kinematic>
      </link>
      <link name='index2'>
        <pose frame=''>0.038994 -0.685352 0.136372 0 0.174533 -0.011537</pose>
        <inertial>
          <pose frame=''>-0.000841 -0.012689 0.000573 0 -0 0</pose>
          <mass>0.00344764</mass>
          <inertia>
            <ixx>3.63785e-07</ixx>
            <ixy>-6.41791e-09</ixy>
            <ixz>7.97765e-10</ixz>
            <iyy>1.07105e-07</iyy>
            <iyz>2.03273e-08</iyz>
            <izz>3.57435e-07</izz>
          </inertia>
        </inertial>
        <collision name='collision'>
          <pose frame=''>0 -0.01152 0 1.5707 -0 0</pose>
          <geometry>
            <cylinder>
              <length>0.029</length>
              <radius>0.0075</radius>
            </cylinder>
          </geometry>
          <surface>
            <contact>
              <ode>
                <kp>100000</kp>
                <kd>10</kd>
                <max_vel>0.1</max_vel>
                <min_depth>0.0015</min_depth>
              </ode>
            </contact>
            <bounce/>
            <friction>
              <torsional>
                <ode/>
              </torsional>
              <ode/>
            </friction>
          </surface>
          <max_contacts>10</max_contacts>
        </collision>
        <collision name='collision_1'>
          <pose frame=''>0 -0.02502 0 0 -0 0</pose>
          <geometry>
            <sphere>
              <radius>0.0075</radius>
            </sphere>
          </geometry>
          <surface>
            <contact>
              <ode>
                <kp>100000</kp>
                <kd>10</kd>
                <max_vel>0.1</max_vel>
                <min_depth>0.0015</min_depth>
              </ode>
            </contact>
            <bounce/>
            <friction>
              <torsional>
                <ode/>
              </torsional>
              <ode/>
            </friction>
          </surface>
          <max_contacts>10</max_contacts>
        </collision>
        <visual name='visual'>
          <geometry>
            <mesh>
              <uri>model://mpl_right_arm/meshes/index2.stl</uri>
            </mesh>
          </geometry>
          <material>
            <script>
              <name>Gazebo/FlatBlack</name>
              <uri>__default__</uri>
            </script>
          </material>
        </visual>
        <sensor name='index2_contact_sensor' type='contact'>
          <contact>
            <collision>collision</collision>
            <collision>collision_1</collision>
            <topic>~/index2/contact</topic>
          </contact>
        </sensor>
        <self_collide>0</self_collide>
        <enable_wind>0</enable_wind>
        <kinematic>0</kinematic>
      </link>
      <link name='index3'>
        <pose frame=''>0.038086 -0.709843 0.136482 0 0.174533 -0.011537</pose>
        <inertial>
          <pose frame=''>4.3e-05 -0.012532 0.000903 0 -0 0</pose>
          <mass>0.00274415</mass>
          <inertia>
            <ixx>1.09202e-07</ixx>
            <ixy>-3.99165e-12</ixy>
            <ixz>-5.84792e-12</ixz>
            <iyy>7.79728e-08</iyy>
            <iyz>2.77966e-09</iyz>
            <izz>1.19449e-07</izz>
          </inertia>
        </inertial>
        <collision name='collision'>
          <pose frame=''>0 -0.00688 0.0001 1.5707 -0 0</pose>
          <geometry>
            <cylinder>
              <length>0.01376</length>
              <radius>0.0074</radius>
            </cylinder>
          </geometry>
          <surface>
            <contact>
              <ode>
                <kp>100000</kp>
                <kd>10</kd>
                <max_vel>0.1</max_vel>
                <min_depth>0.0015</min_depth>
              </ode>
            </contact>
            <bounce/>
            <friction>
              <torsional>
                <ode/>
              </torsional>
              <ode/>
            </friction>
          </surface>
          <max_contacts>10</max_contacts>
        </collision>
        <collision name='collision_1'>
          <pose frame=''>0 -0.015 0.0001 0 -0 0</pose>
          <geometry>
            <sphere>
              <radius>0.0072</radius>
            </sphere>
          </geometry>
          <surface>
            <contact>
              <ode>
                <kp>100000</kp>
                <kd>10</kd>
                <max_vel>0.1</max_vel>
                <min_depth>0.0015</min_depth>
              </ode>
            </contact>
            <bounce/>
            <friction>
              <torsional>
                <ode/>
              </torsional>
              <ode/>
            </friction>
          </surface>
          <max_contacts>10</max_contacts>
        </collision>
        <visual name='visual'>
          <geometry>
            <mesh>
              <uri>model://mpl_right_arm/meshes/index3.stl</uri>
            </mesh>
          </geometry>
          <material>
            <script>
              <name>Gazebo/FlatBlack</name>
              <uri>__default__</uri>
            </script>
          </material>
        </visual>
        <sensor name='index3_contact_sensor' type='contact'>
          <contact>
            <collision>collision</collision>
            <collision>collision_1</collision>
            <topic>~/index3/contact</topic>
          </contact>
        </sensor>
        <sensor name='index3_imu_sensor' type='imu'>
          <always_on>1</always_on>
          <update_rate>1000</update_rate>
          <imu>
            <angular_velocity>
              <x>
                <noise type='gaussian'>
                  <mean>0</mean>
                  <stddev>0.0002</stddev>
                  <bias_mean>7.5e-06</bias_mean>
                  <bias_stddev>8e-07</bias_stddev>
                </noise>
              </x>
              <y>
                <noise type='gaussian'>
                  <mean>0</mean>
                  <stddev>0.0002</stddev>
                  <bias_mean>7.5e-06</bias_mean>
                  <bias_stddev>8e-07</bias_stddev>
                </noise>
              </y>
              <z>
                <noise type='gaussian'>
                  <mean>0</mean>
                  <stddev>0.0002</stddev>
                  <bias_mean>7.5e-06</bias_mean>
                  <bias_stddev>8e-07</bias_stddev>
                </noise>
              </z>
            </angular_velocity>
            <linear_acceleration>
              <x>
                <noise type='gaussian'>
                  <mean>0</mean>
                  <stddev>0.017</stddev>
                  <bias_mean>0.1</bias_mean>
                  <bias_stddev>0.001</bias_stddev>
                </noise>
              </x>
              <y>
                <noise type='gaussian'>
                  <mean>0</mean>
                  <stddev>0.017</stddev>
                  <bias_mean>0.1</bias_mean>
                  <bias_stddev>0.001</bias_stddev>
                </noise>
              </y>
              <z>
                <noise type='gaussian'>
                  <mean>0</mean>
                  <stddev>0.017</stddev>
                  <bias_mean>0.1</bias_mean>
                  <bias_stddev>0.001</bias_stddev>
                </noise>
              </z>
            </linear_acceleration>
          </imu>
        </sensor>
        <self_collide>0</self_collide>
        <enable_wind>0</enable_wind>
        <kinematic>0</kinematic>
      </link>
      <link name='middle0'>
        <pose frame=''>0.015668 -0.63568 0.140513 0.087267 0 -0.011537</pose>
        <inertial>
          <pose frame=''>-0.000143 -0.005485 0.000206 0 -0 0</pose>
          <mass>0.00295579</mass>
          <inertia>
            <ixx>4.22374e-07</ixx>
            <ixy>4.23312e-09</ixy>
            <ixz>5.00706e-10</ixz>
            <iyy>1.94048e-07</iyy>
            <iyz>-4.58725e-09</iyz>
            <izz>4.02189e-07</izz>
          </inertia>
        </inertial>
        <collision name='collision'>
          <pose frame=''>0 -0.01339 0 1.5707 -0 0</pose>
          <geometry>
            <cylinder>
              <length>0.028</length>
              <radius>0.01</radius>
            </cylinder>
          </geometry>
          <surface>
            <contact>
              <ode>
                <kp>100000</kp>
                <kd>10</kd>
                <max_vel>0.1</max_vel>
                <min_depth>0.0015</min_depth>
              </ode>
            </contact>
            <bounce/>
            <friction>
              <torsional>
                <ode/>
              </torsional>
              <ode/>
            </friction>
          </surface>
          <max_contacts>10</max_contacts>
        </collision>
        <visual name='visual'>
          <geometry>
            <mesh>
              <uri>model://mpl_right_arm/meshes/middle0.stl</uri>
            </mesh>
          </geometry>
          <material>
            <script>
              <name>Gazebo/FlatBlack</name>
              <uri>__default__</uri>
            </script>
          </material>
        </visual>
        <sensor name='middle0_contact_sensor' type='contact'>
          <contact>
            <collision>collision</collision>
            <topic>~/middle0/contact</topic>
          </contact>
        </sensor>
        <self_collide>0</self_collide>
        <enable_wind>0</enable_wind>
        <kinematic>0</kinematic>
      </link>
      <link name='middle1'>
        <pose frame=''>0.015524 -0.653612 0.138944 0.087266 -0 -0.011537</pose>
        <inertial>
          <pose frame=''>0.000406 -0.021313 0.000656 0 -0 0</pose>
          <mass>0.00478229</mass>
          <inertia>
            <ixx>8.1859e-07</ixx>
            <ixy>-1.28827e-09</ixy>
            <ixz>1.7867e-10</ixz>
            <iyy>3.06545e-07</iyy>
            <iyz>-1.19001e-08</iyz>
            <izz>7.95403e-07</izz>
          </inertia>
        </inertial>
        <collision name='collision'>
          <pose frame=''>0 -0.025 0 1.5707 -0 0</pose>
          <geometry>
            <cylinder>
              <radius>0.01</radius>
              <length>0.03459</length>
            </cylinder>
          </geometry>
          <surface>
            <contact>
              <ode>
                <kp>100000</kp>
                <kd>10</kd>
                <max_vel>0.1</max_vel>
                <min_depth>0.0015</min_depth>
              </ode>
            </contact>
            <bounce/>
            <friction>
              <torsional>
                <ode/>
              </torsional>
              <ode/>
            </friction>
          </surface>
          <max_contacts>10</max_contacts>
        </collision>
        <visual name='visual'>
          <geometry>
            <mesh>
              <uri>model://mpl_right_arm/meshes/middle1.stl</uri>
            </mesh>
          </geometry>
          <material>
            <script>
              <name>Gazebo/FlatBlack</name>
              <uri>__default__</uri>
            </script>
          </material>
        </visual>
        <sensor name='middle1_contact_sensor' type='contact'>
          <contact>
            <collision>collision</collision>
            <topic>~/middle1/contact</topic>
          </contact>
        </sensor>
        <self_collide>0</self_collide>
        <enable_wind>0</enable_wind>
        <kinematic>0</kinematic>
      </link>
      <link name='middle2'>
        <pose frame=''>0.01611 -0.696999 0.135651 0.087267 0 -0.011537</pose>
        <inertial>
          <pose frame=''>-0.000841 -0.012689 0.000573 0 -0 0</pose>
          <mass>0.00344765</mass>
          <inertia>
            <ixx>3.63785e-07</ixx>
            <ixy>-6.41794e-09</ixy>
            <ixz>7.97197e-10</ixz>
            <iyy>1.07106e-07</iyy>
            <iyz>2.03275e-08</iyz>
            <izz>3.57435e-07</izz>
          </inertia>
        </inertial>
        <collision name='collision'>
          <pose frame=''>0 -0.01152 0 1.5707 -0 0</pose>
          <geometry>
            <cylinder>
              <length>0.029</length>
              <radius>0.0075</radius>
            </cylinder>
          </geometry>
          <surface>
            <contact>
              <ode>
                <kp>100000</kp>
                <kd>10</kd>
                <max_vel>0.1</max_vel>
                <min_depth>0.0015</min_depth>
              </ode>
            </contact>
            <bounce/>
            <friction>
              <torsional>
                <ode/>
              </torsional>
              <ode/>
            </friction>
          </surface>
          <max_contacts>10</max_contacts>
        </collision>
        <collision name='collision_1'>
          <pose frame=''>0 -0.02302 0 0 -0 0</pose>
          <geometry>
            <sphere>
              <radius>0.0075</radius>
            </sphere>
          </geometry>
          <surface>
            <contact>
              <ode>
                <kp>100000</kp>
                <kd>10</kd>
                <max_vel>0.1</max_vel>
                <min_depth>0.0015</min_depth>
              </ode>
            </contact>
            <bounce/>
            <friction>
              <torsional>
                <ode/>
              </torsional>
              <ode/>
            </friction>
          </surface>
          <max_contacts>10</max_contacts>
        </collision>
        <visual name='visual'>
          <geometry>
            <mesh>
              <uri>model://mpl_right_arm/meshes/middle2.stl</uri>
            </mesh>
          </geometry>
          <material>
            <script>
              <name>Gazebo/FlatBlack</name>
              <uri>__default__</uri>
            </script>
          </material>
        </visual>
        <sensor name='middle2_contact_sensor' type='contact'>
          <contact>
            <collision>collision</collision>
            <collision>collision_1</collision>
            <topic>~/middle2/contact</topic>
          </contact>
        </sensor>
        <self_collide>0</self_collide>
        <enable_wind>0</enable_wind>
        <kinematic>0</kinematic>
      </link>
      <link name='middle3'>
        <pose frame=''>0.015193 -0.721397 0.133515 0.087266 -0 -0.011537</pose>
        <inertial>
          <pose frame=''>4.3e-05 -0.012532 0.000903 0 -0 0</pose>
          <mass>0.00274417</mass>
          <inertia>
            <ixx>1.09202e-07</ixx>
            <ixy>-3.78001e-12</ixy>
            <ixz>-5.35395e-12</ixz>
            <iyy>7.79738e-08</iyy>
            <iyz>2.77969e-09</iyz>
            <izz>1.1945e-07</izz>
          </inertia>
        </inertial>
        <collision name='collision'>
          <pose frame=''>0 -0.00688 0.0001 1.5707 -0 0</pose>
          <geometry>
            <cylinder>
              <length>0.01376</length>
              <radius>0.0074</radius>
            </cylinder>
          </geometry>
          <surface>
            <contact>
              <ode>
                <kp>100000</kp>
                <kd>10</kd>
                <max_vel>0.1</max_vel>
                <min_depth>0.0015</min_depth>
              </ode>
            </contact>
            <bounce/>
            <friction>
              <torsional>
                <ode/>
              </torsional>
              <ode/>
            </friction>
          </surface>
          <max_contacts>10</max_contacts>
        </collision>
        <collision name='collision_1'>
          <pose frame=''>0 -0.015 0.0001 0 -0 0</pose>
          <geometry>
            <sphere>
              <radius>0.0072</radius>
            </sphere>
          </geometry>
          <surface>
            <contact>
              <ode>
                <kp>100000</kp>
                <kd>10</kd>
                <max_vel>0.1</max_vel>
                <min_depth>0.0015</min_depth>
              </ode>
            </contact>
            <bounce/>
            <friction>
              <torsional>
                <ode/>
              </torsional>
              <ode/>
            </friction>
          </surface>
          <max_contacts>10</max_contacts>
        </collision>
        <visual name='visual'>
          <geometry>
            <mesh>
              <uri>model://mpl_right_arm/meshes/middle3.stl</uri>
            </mesh>
          </geometry>
          <material>
            <script>
              <name>Gazebo/FlatBlack</name>
              <uri>__default__</uri>
            </script>
          </material>
        </visual>
        <sensor name='middle3_contact_sensor' type='contact'>
          <contact>
            <collision>collision</collision>
            <collision>collision_1</collision>
            <topic>~/middle3/contact</topic>
          </contact>
        </sensor>
        <sensor name='middle3_imu_sensor' type='imu'>
          <always_on>1</always_on>
          <update_rate>1000</update_rate>
          <imu>
            <angular_velocity>
              <x>
                <noise type='gaussian'>
                  <mean>0</mean>
                  <stddev>0.0002</stddev>
                  <bias_mean>7.5e-06</bias_mean>
                  <bias_stddev>8e-07</bias_stddev>
                </noise>
              </x>
              <y>
                <noise type='gaussian'>
                  <mean>0</mean>
                  <stddev>0.0002</stddev>
                  <bias_mean>7.5e-06</bias_mean>
                  <bias_stddev>8e-07</bias_stddev>
                </noise>
              </y>
              <z>
                <noise type='gaussian'>
                  <mean>0</mean>
                  <stddev>0.0002</stddev>
                  <bias_mean>7.5e-06</bias_mean>
                  <bias_stddev>8e-07</bias_stddev>
                </noise>
              </z>
            </angular_velocity>
            <linear_acceleration>
              <x>
                <noise type='gaussian'>
                  <mean>0</mean>
                  <stddev>0.017</stddev>
                  <bias_mean>0.1</bias_mean>
                  <bias_stddev>0.001</bias_stddev>
                </noise>
              </x>
              <y>
                <noise type='gaussian'>
                  <mean>0</mean>
                  <stddev>0.017</stddev>
                  <bias_mean>0.1</bias_mean>
                  <bias_stddev>0.001</bias_stddev>
                </noise>
              </y>
              <z>
                <noise type='gaussian'>
                  <mean>0</mean>
                  <stddev>0.017</stddev>
                  <bias_mean>0.1</bias_mean>
                  <bias_stddev>0.001</bias_stddev>
                </noise>
              </z>
            </linear_acceleration>
          </imu>
        </sensor>
        <self_collide>0</self_collide>
        <enable_wind>0</enable_wind>
        <kinematic>0</kinematic>
      </link>
      <link name='pinky0'>
        <pose frame=''>-0.027501 -0.61268 0.129428 0 -0.174533 -0.011537</pose>
        <inertial>
          <pose frame=''>-0.000143 -0.005385 0.000206 0 -0 0</pose>
          <mass>0.00295579</mass>
          <inertia>
            <ixx>4.22375e-07</ixx>
            <ixy>4.23309e-09</ixy>
            <ixz>5.0054e-10</ixz>
            <iyy>1.94048e-07</iyy>
            <iyz>-4.58693e-09</iyz>
            <izz>4.02189e-07</izz>
          </inertia>
        </inertial>
        <collision name='collision'>
          <pose frame=''>0 -0.01339 0 1.5707 -0 0</pose>
          <geometry>
            <cylinder>
              <length>0.028</length>
              <radius>0.01</radius>
            </cylinder>
          </geometry>
          <surface>
            <contact>
              <ode>
                <kp>100000</kp>
                <kd>10</kd>
                <max_vel>0.1</max_vel>
                <min_depth>0.0015</min_depth>
              </ode>
            </contact>
            <bounce/>
            <friction>
              <torsional>
                <ode/>
              </torsional>
              <ode/>
            </friction>
          </surface>
          <max_contacts>10</max_contacts>
        </collision>
        <visual name='visual'>
          <geometry>
            <mesh>
              <uri>model://mpl_right_arm/meshes/pinky0.stl</uri>
            </mesh>
          </geometry>
          <material>
            <script>
              <name>Gazebo/FlatBlack</name>
              <uri>__default__</uri>
            </script>
          </material>
        </visual>
        <sensor name='pinky0_contact_sensor' type='contact'>
          <contact>
            <collision>collision</collision>
            <topic>~/pinky0/contact</topic>
          </contact>
        </sensor>
        <self_collide>0</self_collide>
        <enable_wind>0</enable_wind>
        <kinematic>0</kinematic>
      </link>
      <link name='pinky1'>
        <pose frame=''>-0.027646 -0.630579 0.129439 0 -0.174533 -0.011537</pose>
        <inertial>
          <pose frame=''>0.000459 -0.016048 0.000925 0 -0 0</pose>
          <mass>0.0034099</mass>
          <inertia>
            <ixx>4.03282e-07</ixx>
            <ixy>-1.80186e-09</ixy>
            <ixz>-1.42049e-09</ixz>
            <iyy>2.20449e-07</iyy>
            <iyz>-9.60174e-09</iyz>
            <izz>3.83588e-07</izz>
          </inertia>
        </inertial>
        <collision name='collision'>
          <pose frame=''>0 -0.02082 0 1.5707 -0 0</pose>
          <geometry>
            <cylinder>
              <radius>0.01</radius>
              <length>0.02381</length>
            </cylinder>
          </geometry>
          <surface>
            <contact>
              <ode>
                <kp>100000</kp>
                <kd>10</kd>
                <max_vel>0.1</max_vel>
                <min_depth>0.0015</min_depth>
              </ode>
            </contact>
            <bounce/>
            <friction>
              <torsional>
                <ode/>
              </torsional>
              <ode/>
            </friction>
          </surface>
          <max_contacts>10</max_contacts>
        </collision>
        <visual name='visual'>
          <geometry>
            <mesh>
              <uri>model://mpl_right_arm/meshes/pinky1.stl</uri>
            </mesh>
          </geometry>
          <material>
            <script>
              <name>Gazebo/FlatBlack</name>
              <uri>__default__</uri>
            </script>
          </material>
        </visual>
        <sensor name='pinky1_contact_sensor' type='contact'>
          <contact>
            <collision>collision</collision>
            <topic>~/pinky0/contact</topic>
          </contact>
        </sensor>
        <self_collide>0</self_collide>
        <enable_wind>0</enable_wind>
        <kinematic>0</kinematic>
      </link>
      <link name='pinky2'>
        <pose frame=''>-0.027544 -0.663582 0.130032 0 -0.174533 -0.011537</pose>
        <inertial>
          <pose frame=''>-0.000271 -0.009146 0.000738 0 -0 0</pose>
          <mass>0.00250622</mass>
          <inertia>
            <ixx>1.78939e-07</ixx>
            <ixy>-3.88097e-09</ixy>
            <ixz>3.24897e-10</ixz>
            <iyy>7.59883e-08</iyy>
            <iyz>1.17825e-08</iyz>
            <izz>1.74551e-07</izz>
          </inertia>
        </inertial>
        <collision name='collision'>
          <pose frame=''>0 -0.0076 0 1.5707 -0 0</pose>
          <geometry>
            <cylinder>
              <length>0.029</length>
              <radius>0.0075</radius>
            </cylinder>
          </geometry>
          <surface>
            <contact>
              <ode>
                <kp>100000</kp>
                <kd>10</kd>
                <max_vel>0.1</max_vel>
                <min_depth>0.0015</min_depth>
              </ode>
            </contact>
            <bounce/>
            <friction>
              <torsional>
                <ode/>
              </torsional>
              <ode/>
            </friction>
          </surface>
          <max_contacts>10</max_contacts>
        </collision>
        <visual name='visual'>
          <geometry>
            <mesh>
              <uri>model://mpl_right_arm/meshes/pinky2.stl</uri>
            </mesh>
          </geometry>
          <material>
            <script>
              <name>Gazebo/FlatBlack</name>
              <uri>__default__</uri>
            </script>
          </material>
        </visual>
        <sensor name='pinky2_contact_sensor' type='contact'>
          <contact>
            <collision>collision</collision>
            <topic>~/pinky2/contact</topic>
          </contact>
        </sensor>
        <self_collide>0</self_collide>
        <enable_wind>0</enable_wind>
        <kinematic>0</kinematic>
      </link>
      <link name='pinky3'>
        <pose frame=''>-0.027793 -0.681081 0.130023 0 -0.174533 -0.011537</pose>
        <inertial>
          <pose frame=''>3.9e-05 -0.012505 0.000912 0 -0 0</pose>
          <mass>0.00273265</mass>
          <inertia>
            <ixx>1.08629e-07</ixx>
            <ixy>2.84178e-11</ixy>
            <ixz>1.88869e-11</ixz>
            <iyy>7.78965e-08</iyy>
            <iyz>2.64344e-09</iyz>
            <izz>1.18971e-07</izz>
          </inertia>
        </inertial>
        <collision name='collision'>
          <pose frame=''>0 -0.00688 0.0001 1.5707 -0 0</pose>
          <geometry>
            <cylinder>
              <length>0.01376</length>
              <radius>0.0074</radius>
            </cylinder>
          </geometry>
          <surface>
            <contact>
              <ode>
                <kp>100000</kp>
                <kd>10</kd>
                <max_vel>0.1</max_vel>
                <min_depth>0.0015</min_depth>
              </ode>
            </contact>
            <bounce/>
            <friction>
              <torsional>
                <ode/>
              </torsional>
              <ode/>
            </friction>
          </surface>
          <max_contacts>10</max_contacts>
        </collision>
        <collision name='collision_1'>
          <pose frame=''>0 -0.015 0.0001 0 -0 0</pose>
          <geometry>
            <sphere>
              <radius>0.0072</radius>
            </sphere>
          </geometry>
          <surface>
            <contact>
              <ode>
                <kp>100000</kp>
                <kd>10</kd>
                <max_vel>0.1</max_vel>
                <min_depth>0.0015</min_depth>
              </ode>
            </contact>
            <bounce/>
            <friction>
              <torsional>
                <ode/>
              </torsional>
              <ode/>
            </friction>
          </surface>
          <max_contacts>10</max_contacts>
        </collision>
        <visual name='visual'>
          <geometry>
            <mesh>
              <uri>model://mpl_right_arm/meshes/pinky3.stl</uri>
            </mesh>
          </geometry>
          <material>
            <script>
              <name>Gazebo/FlatBlack</name>
              <uri>__default__</uri>
            </script>
          </material>
        </visual>
        <sensor name='pinky3_contact_sensor' type='contact'>
          <contact>
            <collision>collision</collision>
            <collision>collision_1</collision>
            <topic>~/pinky3/contact</topic>
          </contact>
        </sensor>
        <sensor name='pinky3_imu_sensor' type='imu'>
          <always_on>1</always_on>
          <update_rate>1000</update_rate>
          <imu>
            <angular_velocity>
              <x>
                <noise type='gaussian'>
                  <mean>0</mean>
                  <stddev>0.0002</stddev>
                  <bias_mean>7.5e-06</bias_mean>
                  <bias_stddev>8e-07</bias_stddev>
                </noise>
              </x>
              <y>
                <noise type='gaussian'>
                  <mean>0</mean>
                  <stddev>0.0002</stddev>
                  <bias_mean>7.5e-06</bias_mean>
                  <bias_stddev>8e-07</bias_stddev>
                </noise>
              </y>
              <z>
                <noise type='gaussian'>
                  <mean>0</mean>
                  <stddev>0.0002</stddev>
                  <bias_mean>7.5e-06</bias_mean>
                  <bias_stddev>8e-07</bias_stddev>
                </noise>
              </z>
            </angular_velocity>
            <linear_acceleration>
              <x>
                <noise type='gaussian'>
                  <mean>0</mean>
                  <stddev>0.017</stddev>
                  <bias_mean>0.1</bias_mean>
                  <bias_stddev>0.001</bias_stddev>
                </noise>
              </x>
              <y>
                <noise type='gaussian'>
                  <mean>0</mean>
                  <stddev>0.017</stddev>
                  <bias_mean>0.1</bias_mean>
                  <bias_stddev>0.001</bias_stddev>
                </noise>
              </y>
              <z>
                <noise type='gaussian'>
                  <mean>0</mean>
                  <stddev>0.017</stddev>
                  <bias_mean>0.1</bias_mean>
                  <bias_stddev>0.001</bias_stddev>
                </noise>
              </z>
            </linear_acceleration>
          </imu>
        </sensor>
        <self_collide>0</self_collide>
        <enable_wind>0</enable_wind>
        <kinematic>0</kinematic>
      </link>
      <link name='ring0'>
        <pose frame=''>-0.00688 -0.624218 0.136579 0 -0.174533 -0.011537</pose>
        <inertial>
          <pose frame=''>-0.000143 -0.005485 0.000206 0 -0 0</pose>
          <mass>0.00295579</mass>
          <inertia>
            <ixx>4.22375e-07</ixx>
            <ixy>4.23309e-09</ixy>
            <ixz>5.00535e-10</ixz>
            <iyy>1.94048e-07</iyy>
            <iyz>-4.58693e-09</iyz>
            <izz>4.02189e-07</izz>
          </inertia>
        </inertial>
        <collision name='collision'>
          <pose frame=''>0 -0.01339 0 1.5707 -0 0</pose>
          <geometry>
            <cylinder>
              <length>0.028</length>
              <radius>0.01</radius>
            </cylinder>
          </geometry>
          <surface>
            <contact>
              <ode>
                <kp>100000</kp>
                <kd>10</kd>
                <max_vel>0.1</max_vel>
                <min_depth>0.0015</min_depth>
              </ode>
            </contact>
            <bounce/>
            <friction>
              <torsional>
                <ode/>
              </torsional>
              <ode/>
            </friction>
          </surface>
          <max_contacts>10</max_contacts>
        </collision>
        <visual name='visual'>
          <geometry>
            <mesh>
              <uri>model://mpl_right_arm/meshes/ring0.stl</uri>
            </mesh>
          </geometry>
          <material>
            <script>
              <name>Gazebo/FlatBlack</name>
              <uri>__default__</uri>
            </script>
          </material>
        </visual>
        <sensor name='ring0_contact_sensor' type='contact'>
          <contact>
            <collision>collision</collision>
            <topic>~/ring0/contact</topic>
          </contact>
        </sensor>
        <self_collide>0</self_collide>
        <enable_wind>0</enable_wind>
        <kinematic>0</kinematic>
      </link>
      <link name='ring1'>
        <pose frame=''>-0.007026 -0.642218 0.13659 0 -0.174533 -0.011537</pose>
        <inertial>
          <pose frame=''>0.000406 -0.021313 0.000656 0 -0 0</pose>
          <mass>0.00478232</mass>
          <inertia>
            <ixx>8.18592e-07</ixx>
            <ixy>-1.28783e-09</ixy>
            <ixz>1.78814e-10</ixz>
            <iyy>3.06546e-07</iyy>
            <iyz>-1.19e-08</iyz>
            <izz>7.95405e-07</izz>
          </inertia>
        </inertial>
        <collision name='collision'>
          <pose frame=''>0 -0.02505 0 1.5707 -0 0</pose>
          <geometry>
            <cylinder>
              <radius>0.01</radius>
              <length>0.03095</length>
            </cylinder>
          </geometry>
          <surface>
            <contact>
              <ode>
                <kp>100000</kp>
                <kd>10</kd>
                <max_vel>0.1</max_vel>
                <min_depth>0.0015</min_depth>
              </ode>
            </contact>
            <bounce/>
            <friction>
              <torsional>
                <ode/>
              </torsional>
              <ode/>
            </friction>
          </surface>
          <max_contacts>10</max_contacts>
        </collision>
        <visual name='visual'>
          <geometry>
            <mesh>
              <uri>model://mpl_right_arm/meshes/ring1.stl</uri>
            </mesh>
          </geometry>
          <material>
            <script>
              <name>Gazebo/FlatBlack</name>
              <uri>__default__</uri>
            </script>
          </material>
        </visual>
        <sensor name='ring1_contact_sensor' type='contact'>
          <contact>
            <collision>collision</collision>
            <topic>~/ring1/contact</topic>
          </contact>
        </sensor>
        <self_collide>0</self_collide>
        <enable_wind>0</enable_wind>
        <kinematic>0</kinematic>
      </link>
      <link name='ring2'>
        <pose frame=''>-0.006545 -0.685726 0.137271 0 -0.174533 -0.011537</pose>
        <inertial>
          <pose frame=''>-0.000842 -0.012689 0.000573 0 -0 0</pose>
          <mass>0.00344767</mass>
          <inertia>
            <ixx>3.63785e-07</ixx>
            <ixy>-6.41744e-09</ixy>
            <ixz>7.98585e-10</ixz>
            <iyy>1.07107e-07</iyy>
            <iyz>2.03271e-08</iyz>
            <izz>3.57437e-07</izz>
          </inertia>
        </inertial>
        <collision name='collision'>
          <pose frame=''>0 -0.01152 0 1.5707 -0 0</pose>
          <geometry>
            <cylinder>
              <length>0.029</length>
              <radius>0.0075</radius>
            </cylinder>
          </geometry>
          <surface>
            <contact>
              <ode>
                <kp>100000</kp>
                <kd>10</kd>
                <max_vel>0.1</max_vel>
                <min_depth>0.0015</min_depth>
              </ode>
            </contact>
            <bounce/>
            <friction>
              <torsional>
                <ode/>
              </torsional>
              <ode/>
            </friction>
          </surface>
          <max_contacts>10</max_contacts>
        </collision>
        <collision name='collision_1'>
          <pose frame=''>0 -0.02302 0 0 -0 0</pose>
          <geometry>
            <sphere>
              <radius>0.0075</radius>
            </sphere>
          </geometry>
          <surface>
            <contact>
              <ode>
                <kp>100000</kp>
                <kd>10</kd>
                <max_vel>0.1</max_vel>
                <min_depth>0.0015</min_depth>
              </ode>
            </contact>
            <bounce/>
            <friction>
              <torsional>
                <ode/>
              </torsional>
              <ode/>
            </friction>
          </surface>
          <max_contacts>10</max_contacts>
        </collision>
        <visual name='visual'>
          <geometry>
            <mesh>
              <uri>model://mpl_right_arm/meshes/ring2.stl</uri>
            </mesh>
          </geometry>
          <material>
            <script>
              <name>Gazebo/FlatBlack</name>
              <uri>__default__</uri>
            </script>
          </material>
        </visual>
        <sensor name='ring2_contact_sensor' type='contact'>
          <contact>
            <collision>collision</collision>
            <topic>~/ring2/contact</topic>
          </contact>
        </sensor>
        <self_collide>0</self_collide>
        <enable_wind>0</enable_wind>
        <kinematic>0</kinematic>
      </link>
      <link name='ring3'>
        <pose frame=''>-0.007453 -0.710217 0.13716 0 -0.174533 -0.011537</pose>
        <inertial>
          <pose frame=''>4.3e-05 -0.012532 0.000903 0 -0 0</pose>
          <mass>0.00274416</mass>
          <inertia>
            <ixx>1.09202e-07</ixx>
            <ixy>-3.99392e-12</ixy>
            <ixz>-5.71287e-12</ixz>
            <iyy>7.79732e-08</iyy>
            <iyz>2.77976e-09</iyz>
            <izz>1.1945e-07</izz>
          </inertia>
        </inertial>
        <collision name='collision'>
          <pose frame=''>0 -0.00688 0.0001 1.5707 -0 0</pose>
          <geometry>
            <cylinder>
              <length>0.01376</length>
              <radius>0.0074</radius>
            </cylinder>
          </geometry>
          <surface>
            <contact>
              <ode>
                <kp>100000</kp>
                <kd>10</kd>
                <max_vel>0.1</max_vel>
                <min_depth>0.0015</min_depth>
              </ode>
            </contact>
            <bounce/>
            <friction>
              <torsional>
                <ode/>
              </torsional>
              <ode/>
            </friction>
          </surface>
          <max_contacts>10</max_contacts>
        </collision>
        <collision name='collision_1'>
          <pose frame=''>0 -0.015 0.0001 0 -0 0</pose>
          <geometry>
            <sphere>
              <radius>0.0072</radius>
            </sphere>
          </geometry>
          <surface>
            <contact>
              <ode>
                <kp>100000</kp>
                <kd>10</kd>
                <max_vel>0.1</max_vel>
                <min_depth>0.0015</min_depth>
              </ode>
            </contact>
            <bounce/>
            <friction>
              <torsional>
                <ode/>
              </torsional>
              <ode/>
            </friction>
          </surface>
          <max_contacts>10</max_contacts>
        </collision>
        <visual name='visual'>
          <geometry>
            <mesh>
              <uri>model://mpl_right_arm/meshes/ring3.stl</uri>
            </mesh>
          </geometry>
          <material>
            <script>
              <name>Gazebo/FlatBlack</name>
              <uri>__default__</uri>
            </script>
          </material>
        </visual>
        <sensor name='ring3_contact_sensor' type='contact'>
          <contact>
            <collision>collision</collision>
            <collision>collision_1</collision>
            <topic>~/ring3/contact</topic>
          </contact>
        </sensor>
        <sensor name='ring3_imu_sensor' type='imu'>
          <always_on>1</always_on>
          <update_rate>1000</update_rate>
          <imu>
            <angular_velocity>
              <x>
                <noise type='gaussian'>
                  <mean>0</mean>
                  <stddev>0.0002</stddev>
                  <bias_mean>7.5e-06</bias_mean>
                  <bias_stddev>8e-07</bias_stddev>
                </noise>
              </x>
              <y>
                <noise type='gaussian'>
                  <mean>0</mean>
                  <stddev>0.0002</stddev>
                  <bias_mean>7.5e-06</bias_mean>
                  <bias_stddev>8e-07</bias_stddev>
                </noise>
              </y>
              <z>
                <noise type='gaussian'>
                  <mean>0</mean>
                  <stddev>0.0002</stddev>
                  <bias_mean>7.5e-06</bias_mean>
                  <bias_stddev>8e-07</bias_stddev>
                </noise>
              </z>
            </angular_velocity>
            <linear_acceleration>
              <x>
                <noise type='gaussian'>
                  <mean>0</mean>
                  <stddev>0.017</stddev>
                  <bias_mean>0.1</bias_mean>
                  <bias_stddev>0.001</bias_stddev>
                </noise>
              </x>
              <y>
                <noise type='gaussian'>
                  <mean>0</mean>
                  <stddev>0.017</stddev>
                  <bias_mean>0.1</bias_mean>
                  <bias_stddev>0.001</bias_stddev>
                </noise>
              </y>
              <z>
                <noise type='gaussian'>
                  <mean>0</mean>
                  <stddev>0.017</stddev>
                  <bias_mean>0.1</bias_mean>
                  <bias_stddev>0.001</bias_stddev>
                </noise>
              </z>
            </linear_acceleration>
          </imu>
        </sensor>
        <self_collide>0</self_collide>
        <enable_wind>0</enable_wind>
        <kinematic>0</kinematic>
      </link>
      <link name='thumb0'>
        <pose frame=''>0.037499 -0.578725 0.124974 0.087376 -0.03058 -0.276903</pose>
        <inertial>
          <pose frame=''>0.008633 -0.000157 -0.000946 0 -0 0</pose>
          <mass>0.00336696</mass>
          <inertia>
            <ixx>2.44266e-07</ixx>
            <ixy>-1.56849e-08</ixy>
            <ixz>4.05807e-08</ixz>
            <iyy>4.49559e-07</iyy>
            <iyz>3.27736e-09</iyz>
            <izz>4.40718e-07</izz>
          </inertia>
        </inertial>
        <collision name='collision'>
          <pose frame=''>0.02 -0.001 0.0015 0 -0 0</pose>
          <geometry>
            <cylinder>
              <length>0.023</length>
              <radius>0.008221</radius>
            </cylinder>
          </geometry>
          <surface>
            <contact>
              <ode>
                <kp>100000</kp>
                <kd>10</kd>
                <max_vel>0.1</max_vel>
                <min_depth>0.0015</min_depth>
              </ode>
            </contact>
            <bounce/>
            <friction>
              <torsional>
                <ode/>
              </torsional>
              <ode/>
            </friction>
          </surface>
          <max_contacts>10</max_contacts>
        </collision>
        <collision name='collision_1'>
          <pose frame=''>0.01 -0.001 0.0015 0 -0 0</pose>
          <geometry>
            <box>
              <size>0.0202 0.0155 0.023</size>
            </box>
          </geometry>
          <surface>
            <contact>
              <ode>
                <kp>100000</kp>
                <kd>10</kd>
                <max_vel>0.1</max_vel>
                <min_depth>0.0015</min_depth>
              </ode>
            </contact>
            <bounce/>
            <friction>
              <torsional>
                <ode/>
              </torsional>
              <ode/>
            </friction>
          </surface>
          <max_contacts>10</max_contacts>
        </collision>
        <visual name='visual'>
          <geometry>
            <mesh>
              <uri>model://mpl_right_arm/meshes/thumb0.stl</uri>
            </mesh>
          </geometry>
          <material>
            <script>
              <name>Gazebo/FlatBlack</name>
              <uri>__default__</uri>
            </script>
          </material>
        </visual>
        <sensor name='thumb0_contact_sensor' type='contact'>
          <contact>
            <collision>collision</collision>
            <collision>collision_1</collision>
            <topic>~/thumb0/contact</topic>
          </contact>
        </sensor>
        <self_collide>0</self_collide>
        <enable_wind>0</enable_wind>
        <kinematic>0</kinematic>
      </link>
      <link name='thumb1'>
        <pose frame=''>0.057306 -0.585356 0.126981 0.087376 -0.03058 -0.276903</pose>
        <inertial>
          <pose frame=''>0.019024 0.000361 -0.000187 0 -0 0</pose>
          <mass>0.00596213</mass>
          <inertia>
            <ixx>5.36423e-07</ixx>
            <ixy>-7.9696e-09</ixy>
            <ixz>-3.66761e-08</ixz>
            <iyy>9.87852e-07</iyy>
            <iyz>-1.23551e-09</iyz>
            <izz>9.4184e-07</izz>
          </inertia>
        </inertial>
        <collision name='collision'>
          <pose frame=''>-0.00056 0 -0.00025 0 -0 0</pose>
          <geometry>
            <cylinder>
              <length>0.0188</length>
              <radius>0.00688</radius>
            </cylinder>
          </geometry>
          <surface>
            <contact>
              <ode>
                <kp>100000</kp>
                <kd>10</kd>
                <max_vel>0.1</max_vel>
                <min_depth>0.0015</min_depth>
              </ode>
            </contact>
            <bounce/>
            <friction>
              <torsional>
                <ode/>
              </torsional>
              <ode/>
            </friction>
          </surface>
          <max_contacts>10</max_contacts>
        </collision>
        <collision name='collision_1'>
          <pose frame=''>0.03381 0 0 0 -0 0</pose>
          <geometry>
            <cylinder>
              <length>0.02176</length>
              <radius>0.00688</radius>
            </cylinder>
          </geometry>
          <surface>
            <contact>
              <ode>
                <kp>100000</kp>
                <kd>10</kd>
                <max_vel>0.1</max_vel>
                <min_depth>0.0015</min_depth>
              </ode>
            </contact>
            <bounce/>
            <friction>
              <torsional>
                <ode/>
              </torsional>
              <ode/>
            </friction>
          </surface>
          <max_contacts>10</max_contacts>
        </collision>
        <collision name='collision_2'>
          <pose frame=''>0.01613 0 0 0 -0 0</pose>
          <geometry>
            <box>
              <size>0.03273 0.01376 0.02176</size>
            </box>
          </geometry>
          <surface>
            <contact>
              <ode>
                <kp>100000</kp>
                <kd>10</kd>
                <max_vel>0.1</max_vel>
                <min_depth>0.0015</min_depth>
              </ode>
            </contact>
            <bounce/>
            <friction>
              <torsional>
                <ode/>
              </torsional>
              <ode/>
            </friction>
          </surface>
          <max_contacts>10</max_contacts>
        </collision>
        <visual name='visual'>
          <geometry>
            <mesh>
              <uri>model://mpl_right_arm/meshes/thumb1.stl</uri>
            </mesh>
          </geometry>
          <material>
            <script>
              <name>Gazebo/FlatBlack</name>
              <uri>__default__</uri>
            </script>
          </material>
        </visual>
        <sensor name='thumb1_contact_sensor' type='contact'>
          <contact>
            <collision>collision</collision>
            <collision>collision_1</collision>
            <collision>collision_2</collision>
            <topic>~/thumb1/contact</topic>
          </contact>
        </sensor>
        <self_collide>0</self_collide>
        <enable_wind>0</enable_wind>
        <kinematic>0</kinematic>
      </link>
      <link name='thumb2'>
        <pose frame=''>0.089554 -0.594453 0.127266 0.087376 -0.03058 -0.276903</pose>
        <inertial>
          <pose frame=''>0.018897 0.000376 0.000654 0 -0 0</pose>
          <mass>0.00599792</mass>
          <inertia>
            <ixx>5.17385e-07</ixx>
            <ixy>-1.08936e-08</ixy>
            <ixz>-3.49348e-08</ixz>
            <iyy>9.9639e-07</iyy>
            <iyz>5.15558e-10</iyz>
            <izz>9.6228e-07</izz>
          </inertia>
        </inertial>
        <collision name='collision'>
          <pose frame=''>0.03415 0 0.001 0 -0 0</pose>
          <geometry>
            <cylinder>
              <radius>0.00679</radius>
              <length>0.02236</length>
            </cylinder>
          </geometry>
          <surface>
            <contact>
              <ode>
                <kp>100000</kp>
                <kd>10</kd>
                <max_vel>0.1</max_vel>
                <min_depth>0.0015</min_depth>
              </ode>
            </contact>
            <bounce/>
            <friction>
              <torsional>
                <ode/>
              </torsional>
              <ode/>
            </friction>
          </surface>
          <max_contacts>10</max_contacts>
        </collision>
        <collision name='collision_1'>
          <pose frame=''>0.01493 0 0.001 0 -0 0</pose>
          <geometry>
            <box>
              <size>0.03095 0.015 0.02236</size>
            </box>
          </geometry>
          <surface>
            <contact>
              <ode>
                <kp>100000</kp>
                <kd>10</kd>
                <max_vel>0.1</max_vel>
                <min_depth>0.0015</min_depth>
              </ode>
            </contact>
            <bounce/>
            <friction>
              <torsional>
                <ode/>
              </torsional>
              <ode/>
            </friction>
          </surface>
          <max_contacts>10</max_contacts>
        </collision>
        <visual name='visual'>
          <geometry>
            <mesh>
              <uri>model://mpl_right_arm/meshes/thumb2.stl</uri>
            </mesh>
          </geometry>
          <material>
            <script>
              <name>Gazebo/FlatBlack</name>
              <uri>__default__</uri>
            </script>
          </material>
        </visual>
        <sensor name='thumb2_contact_sensor' type='contact'>
          <contact>
            <collision>collision</collision>
            <collision>collision_1</collision>
            <topic>~/thumb2/contact</topic>
          </contact>
        </sensor>
        <self_collide>0</self_collide>
        <enable_wind>0</enable_wind>
        <kinematic>0</kinematic>
      </link>
      <link name='thumb3'>
        <pose frame=''>0.121705 -0.603689 0.129371 0.087376 -0.03058 -0.276903</pose>
        <inertial>
          <pose frame=''>0.012344 -0.001455 0 0 -0 0</pose>
          <mass>0.00274415</mass>
          <inertia>
            <ixx>1.73184e-07</ixx>
            <ixy>0</ixy>
            <ixz>0</ixz>
            <iyy>3.66499e-07</iyy>
            <iyz>2.77966e-09</iyz>
            <izz>3.59291e-07</izz>
          </inertia>
        </inertial>
        <collision name='collision'>
          <pose frame=''>0.01507 -0.00219 0.0001 0 -0 0</pose>
          <geometry>
            <cylinder>
              <length>0.01476</length>
              <radius>0.0074</radius>
            </cylinder>
          </geometry>
          <surface>
            <contact>
              <ode>
                <kp>100000</kp>
                <kd>10</kd>
                <max_vel>0.1</max_vel>
                <min_depth>0.0015</min_depth>
              </ode>
            </contact>
            <bounce/>
            <friction>
              <torsional>
                <ode/>
              </torsional>
              <ode/>
            </friction>
          </surface>
          <max_contacts>10</max_contacts>
        </collision>
        <collision name='collision_1'>
          <pose frame=''>0.0195 0 0 0 -0 0</pose>
          <geometry>
            <sphere>
              <radius>0.008</radius>
            </sphere>
          </geometry>
          <surface>
            <contact>
              <ode>
                <kp>100000</kp>
                <kd>10</kd>
                <max_vel>0.1</max_vel>
                <min_depth>0.0015</min_depth>
              </ode>
            </contact>
            <bounce/>
            <friction>
              <torsional>
                <ode/>
              </torsional>
              <ode/>
            </friction>
          </surface>
          <max_contacts>10</max_contacts>
        </collision>
        <visual name='visual'>
          <geometry>
            <mesh>
              <uri>model://mpl_right_arm/meshes/thumb3.stl</uri>
            </mesh>
          </geometry>
          <material>
            <script>
              <name>Gazebo/FlatBlack</name>
              <uri>__default__</uri>
            </script>
          </material>
        </visual>
        <sensor name='thumb3_contact_sensor' type='contact'>
          <contact>
            <collision>collision</collision>
            <collision>collision_1</collision>
            <topic>~/thumb3/contact</topic>
          </contact>
        </sensor>
        <sensor name='thumb3_distal_imu_sensor' type='imu'>
          <always_on>1</always_on>
          <update_rate>1000</update_rate>
          <imu>
            <angular_velocity>
              <x>
                <noise type='gaussian'>
                  <mean>0</mean>
                  <stddev>0.0002</stddev>
                  <bias_mean>7.5e-06</bias_mean>
                  <bias_stddev>8e-07</bias_stddev>
                </noise>
              </x>
              <y>
                <noise type='gaussian'>
                  <mean>0</mean>
                  <stddev>0.0002</stddev>
                  <bias_mean>7.5e-06</bias_mean>
                  <bias_stddev>8e-07</bias_stddev>
                </noise>
              </y>
              <z>
                <noise type='gaussian'>
                  <mean>0</mean>
                  <stddev>0.0002</stddev>
                  <bias_mean>7.5e-06</bias_mean>
                  <bias_stddev>8e-07</bias_stddev>
                </noise>
              </z>
            </angular_velocity>
            <linear_acceleration>
              <x>
                <noise type='gaussian'>
                  <mean>0</mean>
                  <stddev>0.017</stddev>
                  <bias_mean>0.1</bias_mean>
                  <bias_stddev>0.001</bias_stddev>
                </noise>
              </x>
              <y>
                <noise type='gaussian'>
                  <mean>0</mean>
                  <stddev>0.017</stddev>
                  <bias_mean>0.1</bias_mean>
                  <bias_stddev>0.001</bias_stddev>
                </noise>
              </y>
              <z>
                <noise type='gaussian'>
                  <mean>0</mean>
                  <stddev>0.017</stddev>
                  <bias_mean>0.1</bias_mean>
                  <bias_stddev>0.001</bias_stddev>
                </noise>
              </z>
            </linear_acceleration>
          </imu>
        </sensor>
        <self_collide>0</self_collide>
        <enable_wind>0</enable_wind>
        <kinematic>0</kinematic>
      </link>
      <joint name='humerus' type='revolute'>
        <child>humerus</child>
        <parent>shoulder</parent>
        <axis>
          <xyz>0.999933 -0.011537 -0</xyz>
          <limit>
            <lower>-3.14</lower>
            <upper>0.345</upper>
            <effort>10000</effort>
            <velocity>0.5</velocity>
          </limit>
          <dynamics>
            <damping>5</damping>
            <spring_reference>0</spring_reference>
            <spring_stiffness>0</spring_stiffness>
          </dynamics>
          <use_parent_model_frame>1</use_parent_model_frame>
        </axis>
        <physics>
          <provide_feedback>1</provide_feedback>
          <ode>
            <implicit_spring_damper>1</implicit_spring_damper>
            <cfm_damping>1</cfm_damping>
            <limit>
              <cfm>0.01</cfm>
              <erp>0</erp>
            </limit>
          </ode>
        </physics>
      </joint>
      <joint name='elbow' type='revolute'>
        <child>elbow</child>
        <parent>humerus</parent>
        <axis>
          <xyz>0.011537 0.999933 -0</xyz>
          <limit>
            <lower>-0.697</lower>
            <upper>1.57</upper>
            <effort>10000</effort>
            <velocity>0.5</velocity>
          </limit>
          <dynamics>
            <damping>5</damping>
            <spring_reference>0</spring_reference>
            <spring_stiffness>0</spring_stiffness>
          </dynamics>
          <use_parent_model_frame>1</use_parent_model_frame>
        </axis>
        <physics>
          <provide_feedback>1</provide_feedback>
          <ode>
            <implicit_spring_damper>1</implicit_spring_damper>
            <cfm_damping>1</cfm_damping>
            <limit>
              <cfm>0.01</cfm>
              <erp>0</erp>
            </limit>
          </ode>
        </physics>
      </joint>
      <joint name='forearm' type='revolute'>
        <child>forearm</child>
        <parent>elbow</parent>
        <axis>
          <xyz>0 0 1</xyz>
          <limit>
            <lower>0</lower>
            <upper>2.61</upper>
            <effort>10000</effort>
            <velocity>0.5</velocity>
          </limit>
          <dynamics>
            <damping>5</damping>
            <spring_reference>0</spring_reference>
            <spring_stiffness>0</spring_stiffness>
          </dynamics>
          <use_parent_model_frame>1</use_parent_model_frame>
        </axis>
        <physics>
          <provide_feedback>1</provide_feedback>
          <ode>
            <implicit_spring_damper>1</implicit_spring_damper>
            <cfm_damping>1</cfm_damping>
            <limit>
              <cfm>0.01</cfm>
              <erp>0</erp>
            </limit>
          </ode>
        </physics>
      </joint>
      <joint name='wristy' type='revolute'>
        <child>wristy</child>
        <parent>forearm</parent>
        <axis>
          <xyz>0.011537 0.999933 -0</xyz>
          <limit>
            <lower>-1.57</lower>
            <upper>1.57</upper>
            <effort>10000</effort>
            <velocity>0.5</velocity>
          </limit>
          <dynamics>
            <damping>5</damping>
            <spring_reference>0</spring_reference>
            <spring_stiffness>0</spring_stiffness>
          </dynamics>
          <use_parent_model_frame>1</use_parent_model_frame>
        </axis>
        <physics>
          <provide_feedback>1</provide_feedback>
          <ode>
            <implicit_spring_damper>1</implicit_spring_damper>
            <cfm_damping>1</cfm_damping>
            <limit>
              <cfm>0</cfm>
              <erp>0.2</erp>
            </limit>
          </ode>
        </physics>
      </joint>
      <joint name='wristx' type='revolute'>
        <child>wristx</child>
        <parent>wristy</parent>
        <axis>
          <xyz>-0 -0 -1</xyz>
          <limit>
            <lower>-0.261</lower>
            <upper>0.785</upper>
            <effort>10000</effort>
            <velocity>0.5</velocity>
          </limit>
          <dynamics>
            <damping>5</damping>
            <spring_reference>0</spring_reference>
            <spring_stiffness>0</spring_stiffness>
          </dynamics>
          <use_parent_model_frame>1</use_parent_model_frame>
        </axis>
        <physics>
          <provide_feedback>1</provide_feedback>
          <ode>
            <implicit_spring_damper>1</implicit_spring_damper>
            <cfm_damping>1</cfm_damping>
            <limit>
              <cfm>0</cfm>
              <erp>0.2</erp>
            </limit>
          </ode>
        </physics>
      </joint>
      <joint name='wristz' type='revolute'>
        <child>wristz</child>
        <parent>wristx</parent>
        <axis>
          <xyz>0.999933 -0.011537 -0</xyz>
          <limit>
            <lower>-1.04</lower>
            <upper>1.04</upper>
            <effort>10000</effort>
            <velocity>0.5</velocity>
          </limit>
          <dynamics>
            <damping>5</damping>
            <spring_reference>0</spring_reference>
            <spring_stiffness>0</spring_stiffness>
          </dynamics>
          <use_parent_model_frame>1</use_parent_model_frame>
        </axis>
        <physics>
          <provide_feedback>1</provide_feedback>
          <ode>
            <implicit_spring_damper>1</implicit_spring_damper>
            <cfm_damping>1</cfm_damping>
            <limit>
              <cfm>0</cfm>
              <erp>0.2</erp>
            </limit>
          </ode>
        </physics>
      </joint>
      <joint name='index0' type='revolute'>
        <child>index0</child>
        <parent>wristz</parent>
        <axis>
          <xyz>-0.173637 0.002003 -0.984808</xyz>
          <limit>
            <lower>-0.345</lower>
            <upper>0</upper>
            <effort>10000</effort>
            <velocity>0.5</velocity>
          </limit>
          <dynamics>
            <damping>0.8</damping>
            <spring_reference>0</spring_reference>
            <spring_stiffness>0</spring_stiffness>
          </dynamics>
          <use_parent_model_frame>1</use_parent_model_frame>
        </axis>
        <physics>
          <provide_feedback>1</provide_feedback>
          <ode>
            <implicit_spring_damper>1</implicit_spring_damper>
            <cfm_damping>1</cfm_damping>
            <limit>
              <cfm>0</cfm>
              <erp>0.2</erp>
            </limit>
          </ode>
        </physics>
      </joint>
      <joint name='index1' type='revolute'>
        <child>index1</child>
        <parent>index0</parent>
        <axis>
          <xyz>0.984742 -0.011362 -0.173648</xyz>
          <limit>
            <lower>-0.785</lower>
            <upper>1.57</upper>
            <effort>10000</effort>
            <velocity>0.5</velocity>
          </limit>
          <dynamics>
            <damping>0.8</damping>
            <spring_reference>0</spring_reference>
            <spring_stiffness>0</spring_stiffness>
          </dynamics>
          <use_parent_model_frame>1</use_parent_model_frame>
        </axis>
        <physics>
          <provide_feedback>1</provide_feedback>
          <ode>
            <implicit_spring_damper>1</implicit_spring_damper>
            <cfm_damping>1</cfm_damping>
            <limit>
              <cfm>0</cfm>
              <erp>0.2</erp>
            </limit>
          </ode>
        </physics>
      </joint>
      <joint name='index2' type='revolute'>
        <child>index2</child>
        <parent>index1</parent>
        <axis>
          <xyz>0.984742 -0.011362 -0.173648</xyz>
          <limit>
            <lower>0</lower>
            <upper>1.72</upper>
            <effort>10000</effort>
            <velocity>0.5</velocity>
          </limit>
          <dynamics>
            <damping>0.8</damping>
            <spring_reference>0</spring_reference>
            <spring_stiffness>0</spring_stiffness>
          </dynamics>
          <use_parent_model_frame>1</use_parent_model_frame>
        </axis>
        <physics>
          <provide_feedback>1</provide_feedback>
          <ode>
            <implicit_spring_damper>1</implicit_spring_damper>
            <cfm_damping>1</cfm_damping>
            <limit>
              <cfm>0</cfm>
              <erp>0.2</erp>
            </limit>
          </ode>
        </physics>
      </joint>
      <joint name='index3' type='revolute'>
        <child>index3</child>
        <parent>index2</parent>
        <axis>
          <xyz>0.984742 -0.011362 -0.173648</xyz>
          <limit>
            <lower>0</lower>
            <upper>1.38</upper>
            <effort>10000</effort>
            <velocity>0.5</velocity>
          </limit>
          <dynamics>
            <damping>0.8</damping>
            <spring_reference>0</spring_reference>
            <spring_stiffness>0</spring_stiffness>
          </dynamics>
          <use_parent_model_frame>1</use_parent_model_frame>
        </axis>
        <physics>
          <provide_feedback>1</provide_feedback>
          <ode>
            <implicit_spring_damper>1</implicit_spring_damper>
            <cfm_damping>1</cfm_damping>
            <limit>
              <cfm>0</cfm>
              <erp>0.2</erp>
            </limit>
          </ode>
        </physics>
      </joint>
      <joint name='middle0' type='revolute'>
        <child>middle0</child>
        <parent>wristz</parent>
        <axis>
          <xyz>0.001006 0.08715 -0.996195</xyz>
          <limit>
            <lower>0</lower>
            <upper>0</upper>
            <effort>10000</effort>
            <velocity>0.5</velocity>
          </limit>
          <dynamics>
            <damping>0.8</damping>
            <spring_reference>0</spring_reference>
            <spring_stiffness>0</spring_stiffness>
          </dynamics>
          <use_parent_model_frame>1</use_parent_model_frame>
        </axis>
        <physics>
          <provide_feedback>1</provide_feedback>
          <ode>
            <implicit_spring_damper>1</implicit_spring_damper>
            <cfm_damping>1</cfm_damping>
            <limit>
              <cfm>0</cfm>
              <erp>0.2</erp>
            </limit>
          </ode>
        </physics>
      </joint>
      <joint name='middle1' type='revolute'>
        <child>middle1</child>
        <parent>middle0</parent>
        <axis>
          <xyz>0.999933 -0.011537 -0</xyz>
          <limit>
            <lower>-0.785</lower>
            <upper>1.57</upper>
            <effort>10000</effort>
            <velocity>0.5</velocity>
          </limit>
          <dynamics>
            <damping>0.8</damping>
            <spring_reference>0</spring_reference>
            <spring_stiffness>0</spring_stiffness>
          </dynamics>
          <use_parent_model_frame>1</use_parent_model_frame>
        </axis>
        <physics>
          <provide_feedback>1</provide_feedback>
          <ode>
            <implicit_spring_damper>1</implicit_spring_damper>
            <cfm_damping>1</cfm_damping>
            <limit>
              <cfm>0</cfm>
              <erp>0.2</erp>
            </limit>
          </ode>
        </physics>
      </joint>
      <joint name='middle2' type='revolute'>
        <child>middle2</child>
        <parent>middle1</parent>
        <axis>
          <xyz>0.999933 -0.011537 -0</xyz>
          <limit>
            <lower>0</lower>
            <upper>1.73</upper>
            <effort>10000</effort>
            <velocity>0.5</velocity>
          </limit>
          <dynamics>
            <damping>0.8</damping>
            <spring_reference>0</spring_reference>
            <spring_stiffness>0</spring_stiffness>
          </dynamics>
          <use_parent_model_frame>1</use_parent_model_frame>
        </axis>
        <physics>
          <provide_feedback>1</provide_feedback>
          <ode>
            <implicit_spring_damper>1</implicit_spring_damper>
            <cfm_damping>1</cfm_damping>
            <limit>
              <cfm>0</cfm>
              <erp>0.2</erp>
            </limit>
          </ode>
        </physics>
      </joint>
      <joint name='middle3' type='revolute'>
        <child>middle3</child>
        <parent>middle2</parent>
        <axis>
          <xyz>0.999933 -0.011537 -0</xyz>
          <limit>
            <lower>0</lower>
            <upper>1.38</upper>
            <effort>10000</effort>
            <velocity>0.5</velocity>
          </limit>
          <dynamics>
            <damping>0.8</damping>
            <spring_reference>0</spring_reference>
            <spring_stiffness>0</spring_stiffness>
          </dynamics>
          <use_parent_model_frame>1</use_parent_model_frame>
        </axis>
        <physics>
          <provide_feedback>1</provide_feedback>
          <ode>
            <implicit_spring_damper>1</implicit_spring_damper>
            <cfm_damping>1</cfm_damping>
            <limit>
              <cfm>0</cfm>
              <erp>0.2</erp>
            </limit>
          </ode>
        </physics>
      </joint>
      <joint name='pinky0' type='revolute'>
        <child>pinky0</child>
        <parent>wristz</parent>
        <axis>
          <xyz>0.173637 -0.002003 -0.984808</xyz>
          <limit>
            <lower>0</lower>
            <upper>0.345</upper>
            <effort>10000</effort>
            <velocity>0.5</velocity>
          </limit>
          <dynamics>
            <damping>0.8</damping>
            <spring_reference>0</spring_reference>
            <spring_stiffness>0</spring_stiffness>
          </dynamics>
          <use_parent_model_frame>1</use_parent_model_frame>
        </axis>
        <physics>
          <provide_feedback>1</provide_feedback>
          <ode>
            <implicit_spring_damper>1</implicit_spring_damper>
            <cfm_damping>1</cfm_damping>
            <limit>
              <cfm>0</cfm>
              <erp>0.2</erp>
            </limit>
          </ode>
        </physics>
      </joint>
      <joint name='pinky1' type='revolute'>
        <child>pinky1</child>
        <parent>pinky0</parent>
        <axis>
          <xyz>0.984742 -0.011362 0.173648</xyz>
          <limit>
            <lower>-0.785</lower>
            <upper>1.57</upper>
            <effort>10000</effort>
            <velocity>0.5</velocity>
          </limit>
          <dynamics>
            <damping>0.8</damping>
            <spring_reference>0</spring_reference>
            <spring_stiffness>0</spring_stiffness>
          </dynamics>
          <use_parent_model_frame>1</use_parent_model_frame>
        </axis>
        <physics>
          <provide_feedback>1</provide_feedback>
          <ode>
            <implicit_spring_damper>1</implicit_spring_damper>
            <cfm_damping>1</cfm_damping>
            <limit>
              <cfm>0</cfm>
              <erp>0.2</erp>
            </limit>
          </ode>
        </physics>
      </joint>
      <joint name='pinky2' type='revolute'>
        <child>pinky2</child>
        <parent>pinky1</parent>
        <axis>
          <xyz>0.984742 -0.011362 0.173648</xyz>
          <limit>
            <lower>0</lower>
            <upper>1.72</upper>
            <effort>10000</effort>
            <velocity>0.5</velocity>
          </limit>
          <dynamics>
            <damping>0.8</damping>
            <spring_reference>0</spring_reference>
            <spring_stiffness>0</spring_stiffness>
          </dynamics>
          <use_parent_model_frame>1</use_parent_model_frame>
        </axis>
        <physics>
          <provide_feedback>1</provide_feedback>
          <ode>
            <implicit_spring_damper>1</implicit_spring_damper>
            <cfm_damping>1</cfm_damping>
            <limit>
              <cfm>0</cfm>
              <erp>0.2</erp>
            </limit>
          </ode>
        </physics>
      </joint>
      <joint name='pinky3' type='revolute'>
        <child>pinky3</child>
        <parent>pinky2</parent>
        <axis>
          <xyz>0.984742 -0.011362 0.173648</xyz>
          <limit>
            <lower>0</lower>
            <upper>1.38</upper>
            <effort>10000</effort>
            <velocity>0.5</velocity>
          </limit>
          <dynamics>
            <damping>0.8</damping>
            <spring_reference>0</spring_reference>
            <spring_stiffness>0</spring_stiffness>
          </dynamics>
          <use_parent_model_frame>1</use_parent_model_frame>
        </axis>
        <physics>
          <provide_feedback>1</provide_feedback>
          <ode>
            <implicit_spring_damper>1</implicit_spring_damper>
            <cfm_damping>1</cfm_damping>
            <limit>
              <cfm>0</cfm>
              <erp>0.2</erp>
            </limit>
          </ode>
        </physics>
      </joint>
      <joint name='ring0' type='revolute'>
        <child>ring0</child>
        <parent>wristz</parent>
        <axis>
          <xyz>0.173637 -0.002003 -0.984808</xyz>
          <limit>
            <lower>0</lower>
            <upper>0.345</upper>
            <effort>10000</effort>
            <velocity>0.5</velocity>
          </limit>
          <dynamics>
            <damping>0.8</damping>
            <spring_reference>0</spring_reference>
            <spring_stiffness>0</spring_stiffness>
          </dynamics>
          <use_parent_model_frame>1</use_parent_model_frame>
        </axis>
        <physics>
          <provide_feedback>1</provide_feedback>
          <ode>
            <implicit_spring_damper>1</implicit_spring_damper>
            <cfm_damping>1</cfm_damping>
            <limit>
              <cfm>0</cfm>
              <erp>0.2</erp>
            </limit>
          </ode>
        </physics>
      </joint>
      <joint name='ring1' type='revolute'>
        <child>ring1</child>
        <parent>ring0</parent>
        <axis>
          <xyz>0.984742 -0.011362 0.173648</xyz>
          <limit>
            <lower>-0.785</lower>
            <upper>1.57</upper>
            <effort>10000</effort>
            <velocity>0.5</velocity>
          </limit>
          <dynamics>
            <damping>0.8</damping>
            <spring_reference>0</spring_reference>
            <spring_stiffness>0</spring_stiffness>
          </dynamics>
          <use_parent_model_frame>1</use_parent_model_frame>
        </axis>
        <physics>
          <provide_feedback>1</provide_feedback>
          <ode>
            <implicit_spring_damper>1</implicit_spring_damper>
            <cfm_damping>1</cfm_damping>
            <limit>
              <cfm>0</cfm>
              <erp>0.2</erp>
            </limit>
          </ode>
        </physics>
      </joint>
      <joint name='ring2' type='revolute'>
        <child>ring2</child>
        <parent>ring1</parent>
        <axis>
          <xyz>0.984742 -0.011362 0.173648</xyz>
          <limit>
            <lower>0</lower>
            <upper>1.72</upper>
            <effort>10000</effort>
            <velocity>0.5</velocity>
          </limit>
          <dynamics>
            <damping>0.8</damping>
            <spring_reference>0</spring_reference>
            <spring_stiffness>0</spring_stiffness>
          </dynamics>
          <use_parent_model_frame>1</use_parent_model_frame>
        </axis>
        <physics>
          <provide_feedback>1</provide_feedback>
          <ode>
            <implicit_spring_damper>1</implicit_spring_damper>
            <cfm_damping>1</cfm_damping>
            <limit>
              <cfm>0</cfm>
              <erp>0.2</erp>
            </limit>
          </ode>
        </physics>
      </joint>
      <joint name='ring3' type='revolute'>
        <child>ring3</child>
        <parent>ring2</parent>
        <axis>
          <xyz>0.984742 -0.011362 0.173648</xyz>
          <limit>
            <lower>0</lower>
            <upper>1.38</upper>
            <effort>10000</effort>
            <velocity>0.5</velocity>
          </limit>
          <dynamics>
            <damping>0.8</damping>
            <spring_reference>0</spring_reference>
            <spring_stiffness>0</spring_stiffness>
          </dynamics>
          <use_parent_model_frame>1</use_parent_model_frame>
        </axis>
        <physics>
          <provide_feedback>1</provide_feedback>
          <ode>
            <implicit_spring_damper>1</implicit_spring_damper>
            <cfm_damping>1</cfm_damping>
            <limit>
              <cfm>0</cfm>
              <erp>0.2</erp>
            </limit>
          </ode>
        </physics>
      </joint>
      <joint name='thumb0' type='revolute'>
        <child>thumb0</child>
        <parent>wristz</parent>
        <axis>
          <xyz>0.269769 0.958967 0.087224</xyz>
          <limit>
            <lower>0</lower>
            <upper>2.07</upper>
            <effort>10000</effort>
            <velocity>0.5</velocity>
          </limit>
          <dynamics>
            <damping>0.8</damping>
            <spring_reference>0</spring_reference>
            <spring_stiffness>0</spring_stiffness>
          </dynamics>
          <use_parent_model_frame>1</use_parent_model_frame>
        </axis>
        <physics>
          <provide_feedback>1</provide_feedback>
          <ode>
            <implicit_spring_damper>1</implicit_spring_damper>
            <cfm_damping>1</cfm_damping>
            <limit>
              <cfm>0</cfm>
              <erp>0.2</erp>
            </limit>
          </ode>
        </physics>
      </joint>
      <joint name='thumb1' type='revolute'>
        <child>thumb1</child>
        <parent>thumb0</parent>
        <axis>
          <xyz>0.053155 0.075614 -0.995719</xyz>
          <limit>
            <lower>0</lower>
            <upper>1.03</upper>
            <effort>10000</effort>
            <velocity>0.5</velocity>
          </limit>
          <dynamics>
            <damping>0.8</damping>
            <spring_reference>0</spring_reference>
            <spring_stiffness>0</spring_stiffness>
          </dynamics>
          <use_parent_model_frame>1</use_parent_model_frame>
        </axis>
        <physics>
          <provide_feedback>1</provide_feedback>
          <ode>
            <implicit_spring_damper>1</implicit_spring_damper>
            <cfm_damping>1</cfm_damping>
            <limit>
              <cfm>0</cfm>
              <erp>0.2</erp>
            </limit>
          </ode>
        </physics>
      </joint>
      <joint name='thumb2' type='revolute'>
        <child>thumb2</child>
        <parent>thumb1</parent>
        <axis>
          <xyz>0.053155 0.075614 -0.995719</xyz>
          <limit>
            <lower>0</lower>
            <upper>1.03</upper>
            <effort>10000</effort>
            <velocity>0.5</velocity>
          </limit>
          <dynamics>
            <damping>0.8</damping>
            <spring_reference>0</spring_reference>
            <spring_stiffness>0</spring_stiffness>
          </dynamics>
          <use_parent_model_frame>1</use_parent_model_frame>
        </axis>
        <physics>
          <provide_feedback>1</provide_feedback>
          <ode>
            <implicit_spring_damper>1</implicit_spring_damper>
            <cfm_damping>1</cfm_damping>
            <limit>
              <cfm>0</cfm>
              <erp>0.2</erp>
            </limit>
          </ode>
        </physics>
      </joint>
      <joint name='thumb3' type='revolute'>
        <child>thumb3</child>
        <parent>thumb2</parent>
        <axis>
          <xyz>0.053155 0.075614 -0.995719</xyz>
          <limit>
            <lower>-0.819</lower>
            <upper>1.28</upper>
            <effort>10000</effort>
            <velocity>0.5</velocity>
          </limit>
          <dynamics>
            <damping>0.8</damping>
            <spring_reference>0</spring_reference>
            <spring_stiffness>0</spring_stiffness>
          </dynamics>
          <use_parent_model_frame>1</use_parent_model_frame>
        </axis>
        <physics>
          <provide_feedback>1</provide_feedback>
          <ode>
            <implicit_spring_damper>1</implicit_spring_damper>
            <cfm_damping>1</cfm_damping>
            <limit>
              <cfm>0</cfm>
              <erp>0.2</erp>
            </limit>
          </ode>
        </physics>
      </joint>
      <pose frame=''>1.1195 1.57049 0 0 -0 0</pose>
    </model>
    <model name='plastic_cup'>
      <link name='link'>
        <pose frame=''>0 0 0.065 0 -0 0</pose>
        <inertial>
          <mass>0.0599</mass>
          <inertia>
            <ixx>0.000302896</ixx>
            <ixy>0</ixy>
            <ixz>0</ixz>
            <iyy>0.000302896</iyy>
            <iyz>0</iyz>
            <izz>3.28764e-05</izz>
          </inertia>
        </inertial>
        <collision name='collision'>
          <geometry>
            <mesh>
              <uri>model://plastic_cup/meshes/plastic_cup.dae</uri>
            </mesh>
          </geometry>
          <surface>
            <contact>
              <poissons_ratio>0.35</poissons_ratio>
              <elastic_modulus>3.10264e+09</elastic_modulus>
              <ode>
                <kp>100000</kp>
                <kd>100</kd>
                <max_vel>100</max_vel>
                <min_depth>0.001</min_depth>
              </ode>
            </contact>
            <friction>
              <torsional>
                <coefficient>1</coefficient>
                <use_patch_radius>0</use_patch_radius>
                <surface_radius>0.01</surface_radius>
                <ode/>
              </torsional>
              <ode/>
            </friction>
            <bounce/>
          </surface>
          <max_contacts>10</max_contacts>
        </collision>
        <visual name='visual'>
          <geometry>
            <mesh>
              <uri>model://plastic_cup/meshes/plastic_cup.dae</uri>
            </mesh>
          </geometry>
          <material>
            <script>
              <uri>file://media/materials/scripts/gazebo.material</uri>
              <name>Gazebo/GreyTransparent</name>
            </script>
          </material>
        </visual>
        <self_collide>0</self_collide>
        <enable_wind>0</enable_wind>
        <kinematic>0</kinematic>
      </link>
      <pose frame=''>1.26419 1.28186 0 0 -0 0</pose>
    </model>
    <model name='plastic_cup_0'>
      <link name='link'>
        <pose frame=''>0 0 0.065 0 -0 0</pose>
        <inertial>
          <mass>0.0599</mass>
          <inertia>
            <ixx>0.000302896</ixx>
            <ixy>0</ixy>
            <ixz>0</ixz>
            <iyy>0.000302896</iyy>
            <iyz>0</iyz>
            <izz>3.28764e-05</izz>
          </inertia>
        </inertial>
        <collision name='collision'>
          <geometry>
            <mesh>
              <uri>model://plastic_cup/meshes/plastic_cup.dae</uri>
            </mesh>
          </geometry>
          <surface>
            <contact>
              <poissons_ratio>0.35</poissons_ratio>
              <elastic_modulus>3.10264e+09</elastic_modulus>
              <ode>
                <kp>100000</kp>
                <kd>100</kd>
                <max_vel>100</max_vel>
                <min_depth>0.001</min_depth>
              </ode>
            </contact>
            <friction>
              <torsional>
                <coefficient>1</coefficient>
                <use_patch_radius>0</use_patch_radius>
                <surface_radius>0.01</surface_radius>
                <ode/>
              </torsional>
              <ode/>
            </friction>
            <bounce/>
          </surface>
          <max_contacts>10</max_contacts>
        </collision>
        <visual name='visual'>
          <geometry>
            <mesh>
              <uri>model://plastic_cup/meshes/plastic_cup.dae</uri>
            </mesh>
          </geometry>
          <material>
            <script>
              <uri>file://media/materials/scripts/gazebo.material</uri>
              <name>Gazebo/GreyTransparent</name>
            </script>
          </material>
        </visual>
        <self_collide>0</self_collide>
        <enable_wind>0</enable_wind>
        <kinematic>0</kinematic>
      </link>
      <pose frame=''>1.27602 1.49058 0 0 -0 0</pose>
    </model>
    <state world_name='default'>
      <sim_time>731 655000000</sim_time>
      <real_time>826 272704835</real_time>
      <wall_time>1624438954 454593914</wall_time>
      <iterations>731655</iterations>
      <model name='beer'>
        <pose frame=''>1.60439 1.05931 0.774989 -2e-05 1.8e-05 0.002408</pose>
        <scale>1 1 1</scale>
        <link name='link'>
          <pose frame=''>1.60439 1.05931 0.889989 -2e-05 1.8e-05 0.002408</pose>
          <velocity>0 0 0 0 -0 0</velocity>
          <acceleration>0 0 -9.8 1e-06 2e-06 0</acceleration>
          <wrench>0 0 -3.822 0 -0 0</wrench>
        </link>
      </model>
      <model name='cafe_table'>
        <pose frame=''>1.25656 0.158317 0 0 -0 0</pose>
        <scale>1 1 1</scale>
        <link name='link'>
          <pose frame=''>1.25656 0.158317 0 0 -0 0</pose>
          <velocity>0 0 0 0 -0 0</velocity>
          <acceleration>0 0 0 0 -0 0</acceleration>
          <wrench>0 0 0 0 -0 0</wrench>
        </link>
      </model>
      <model name='cafe_table_0'>
        <pose frame=''>1.25732 -0.706078 0 0 -0 0</pose>
        <scale>1 1 1</scale>
        <link name='link'>
          <pose frame=''>1.25732 -0.706078 0 0 -0 0</pose>
          <velocity>0 0 0 0 -0 0</velocity>
          <acceleration>0 0 0 0 -0 0</acceleration>
          <wrench>0 0 0 0 -0 0</wrench>
        </link>
      </model>
      <model name='cafe_table_1'>
        <pose frame=''>1.26085 0.991577 0 0 -0 0</pose>
        <scale>1 1 1</scale>
        <link name='link'>
          <pose frame=''>1.26085 0.991577 0 0 -0 0</pose>
          <velocity>0 0 0 0 -0 0</velocity>
          <acceleration>0 0 0 0 -0 0</acceleration>
          <wrench>0 0 0 0 -0 0</wrench>
        </link>
      </model>
      <model name='coke_can'>
        <pose frame=''>1.40249 0.049381 0.772415 -0.005126 0.001817 -0.019827</pose>
        <scale>1 1 1</scale>
        <link name='link'>
          <pose frame=''>1.40249 0.049381 0.772415 -0.005126 0.001817 -0.019827</pose>
          <velocity>0 0 0 0 -0 0</velocity>
          <acceleration>0.00287 -0.02446 0.001134 0.425469 0.050338 -0.006095</acceleration>
          <wrench>0.001119 -0.009539 0.000442 0 -0 0</wrench>
        </link>
      </model>
      <model name='ground_plane'>
        <pose frame=''>0 0 0 0 -0 0</pose>
        <scale>1 1 1</scale>
        <link name='link'>
          <pose frame=''>0 0 0 0 -0 0</pose>
          <velocity>0 0 0 0 -0 0</velocity>
          <acceleration>0 0 0 0 -0 0</acceleration>
          <wrench>0 0 0 0 -0 0</wrench>
        </link>
      </model>
      <model name='mpl_right_arm'>
        <pose frame=''>1.11867 0.862893 0.681172 0.020054 -0.014105 -0.012304</pose>
        <scale>1 1 1</scale>
        <link name='elbow'>
          <pose frame=''>1.1132 0.710268 0.813149 0.016374 -0.034384 -0.024189</pose>
          <velocity>-2.9e-05 -2.1e-05 9.3e-05 0.000291 -0.001738 0.000361</velocity>
          <acceleration>-0.035181 -0.02574 0.102736 -2.7121 1.45783 -2.58685</acceleration>
          <wrench>-0.001238 -0.000906 0.003615 0 -0 0</wrench>
        </link>
        <link name='forearm'>
          <pose frame=''>1.12031 0.565914 0.795793 0.016317 -0.03441 -0.022645</pose>
          <velocity>5.4e-05 -1.6e-05 6.7e-05 0.000101 -0.001764 8.7e-05</velocity>
          <acceleration>-0.036016 -0.015122 0.059663 -2.77814 1.43773 -3.05526</acceleration>
          <wrench>-0.003591 -0.001508 0.005948 0 -0 0</wrench>
        </link>
        <link name='humerus'>
          <pose frame=''>1.11858 0.860457 0.801739 0.016366 -0.01387 -0.023853</pose>
          <velocity>-4.6e-05 -1.8e-05 0.00014 0.000353 -0.001825 0.000345</velocity>
          <acceleration>-0.129767 -0.034488 0.158086 0.553965 1.20349 0.555603</acceleration>
          <wrench>-0.011133 -0.002959 0.013562 0 -0 0</wrench>
        </link>
        <link name='index0'>
          <pose frame=''>1.14785 0.236634 0.798274 0.161056 0.169053 0.0232</pose>
          <velocity>8e-06 3e-06 8e-06 0.000133 0.000191 5e-05</velocity>
          <acceleration>-0.026609 0.00475 0.024287 0.454377 -1.1837 0.022524</acceleration>
          <wrench>-7.9e-05 1.4e-05 7.2e-05 0 -0 0</wrench>
        </link>
        <link name='index1'>
          <pose frame=''>1.14783 0.218863 0.795418 0.177535 0.169054 0.0232</pose>
          <velocity>7e-06 2e-06 8e-06 8.5e-05 0.000151 1.9e-05</velocity>
          <acceleration>-0.018835 0.003765 0.019362 0.377511 -1.24113 -0.059426</acceleration>
          <wrench>-9e-05 1.8e-05 9.3e-05 0 -0 0</wrench>
        </link>
        <link name='index2'>
          <pose frame=''>1.14869 0.175966 0.788147 0.177531 0.169055 0.0232</pose>
          <velocity>7e-06 2e-06 4e-06 2.9e-05 0.000276 -6e-06</velocity>
          <acceleration>-0.009905 0.003897 0.007057 0.325186 -1.12026 -0.110087</acceleration>
          <wrench>-3.4e-05 1.3e-05 2.4e-05 0 -0 0</wrench>
        </link>
        <link name='index3'>
          <pose frame=''>1.1479 0.151827 0.783989 0.231004 0.169056 0.023199</pose>
          <velocity>4e-06 1e-06 1e-06 -0.000137 0.000472 4e-06</velocity>
          <acceleration>-0.00564 0.002139 0.000211 -0.283686 -0.742865 -0.021398</acceleration>
          <wrench>-1.5e-05 6e-06 1e-06 0 -0 0</wrench>
        </link>
        <link name='middle0'>
          <pose frame=''>1.12485 0.224577 0.800786 0.24232 -2.5e-05 -0.025314</pose>
          <velocity>6e-06 8e-06 1.3e-05 0.001036 -6.4e-05 4.7e-05</velocity>
          <acceleration>-0.03348 0.007739 0.001687 2.8377 1.0625 2.56457</acceleration>
          <wrench>-9.9e-05 2.3e-05 5e-06 0 -0 0</wrench>
        </link>
        <link name='middle1'>
          <pose frame=''>1.12447 0.207106 0.796467 0.165661 -0.000114 -0.025317</pose>
          <velocity>3e-06 9e-06 8e-06 0.000962 -0.001013 -1.1e-05</velocity>
          <acceleration>-0.021341 0.005871 0.011073 2.6449 -0.761432 2.31252</acceleration>
          <wrench>-0.000102 2.8e-05 5.3e-05 0 -0 0</wrench>
        </link>
        <link name='middle2'>
          <pose frame=''>1.12447 0.164106 0.789787 0.165678 -0.000227 -0.025289</pose>
          <velocity>1.1e-05 1.6e-05 -3.1e-05 -0.001032 0.000756 0.000146</velocity>
          <acceleration>0.04191 0.003381 0.001283 2.36602 0.920668 2.59307</acceleration>
          <wrench>0.000144 1.2e-05 4e-06 0 -0 0</wrench>
        </link>
        <link name='middle3'>
          <pose frame=''>1.12322 0.139965 0.785745 0.349729 -0.000373 -0.025346</pose>
          <velocity>5e-06 1.4e-05 -6e-06 -0.001204 0.001764 0.001257</velocity>
          <acceleration>0.069079 -0.000117 -0.002411 -3.06259 0.505435 -0.670723</acceleration>
          <wrench>0.00019 -0 -7e-06 0 -0 0</wrench>
        </link>
        <link name='pinky0'>
          <pose frame=''>1.08204 0.249619 0.793311 0.158678 -0.171226 -0.060103</pose>
          <velocity>8e-06 6e-06 1.3e-05 -9e-06 0.000147 -3.8e-05</velocity>
          <acceleration>-0.019116 0.009607 -0.06044 -0.999928 -1.28152 -0.10945</acceleration>
          <wrench>-5.7e-05 2.8e-05 -0.000179 0 -0 0</wrench>
        </link>
        <link name='pinky1'>
          <pose frame=''>1.08153 0.231944 0.790535 0.138499 -0.171227 -0.060102</pose>
          <velocity>6e-06 4e-06 1.5e-05 0.000133 0.000153 -2.2e-05</velocity>
          <acceleration>-0.015763 0.007945 -0.036784 -0.942348 -1.2986 -0.058252</acceleration>
          <wrench>-5.4e-05 2.7e-05 -0.000125 0 -0 0</wrench>
        </link>
        <link name='pinky2'>
          <pose frame=''>1.08082 0.199175 0.786632 0.138497 -0.171232 -0.060098</pose>
          <velocity>5e-06 3e-06 1.1e-05 0.000376 0.000243 -1.1e-05</velocity>
          <acceleration>-0.011832 0.005653 -0.015245 -0.79822 -1.23995 -0.097512</acceleration>
          <wrench>-3e-05 1.4e-05 -3.8e-05 0 -0 0</wrench>
        </link>
        <link name='pinky3'>
          <pose frame=''>1.08014 0.181851 0.784243 0.248723 -0.171235 -0.060098</pose>
          <velocity>4e-06 2e-06 -0 -0.000199 0.000345 -1.4e-05</velocity>
          <acceleration>-0.007824 0.003219 0.000583 -0.428162 -1.02077 -0.092166</acceleration>
          <wrench>-2.1e-05 9e-06 2e-06 0 -0 0</wrench>
        </link>
        <link name='ring0'>
          <pose frame=''>1.10248 0.236825 0.79863 0.164125 -0.166009 -0.092604</pose>
          <velocity>8e-06 7e-06 1.3e-05 0.000719 3e-05 0.000138</velocity>
          <acceleration>-0.026245 0.011688 -0.034383 0.075967 -1.28838 0.107366</acceleration>
          <wrench>-7.8e-05 3.5e-05 -0.000102 0 -0 0</wrench>
        </link>
        <link name='ring1'>
          <pose frame=''>1.10138 0.219092 0.79574 0.178275 -0.16601 -0.092603</pose>
          <velocity>8e-06 6e-06 1.2e-05 0.00082 3.5e-05 0.00012</velocity>
          <acceleration>-0.015705 0.01152 -0.035223 0.220188 -1.27872 0.040666</acceleration>
          <wrench>-7.5e-05 5.5e-05 -0.000168 0 -0 0</wrench>
        </link>
        <link name='ring2'>
          <pose frame=''>1.09967 0.176168 0.788797 0.178273 -0.166013 -0.0926</pose>
          <velocity>1.3e-05 1e-05 -1.9e-05 -0.000713 0.000327 -0.000191</velocity>
          <acceleration>-0.006777 0.00999 -0.022335 -1.39309 -1.33875 -0.330715</acceleration>
          <wrench>-2.3e-05 3.4e-05 -7.7e-05 0 -0 0</wrench>
        </link>
        <link name='ring3'>
          <pose frame=''>1.09753 0.152152 0.784407 0.259938 -0.166018 -0.092601</pose>
          <velocity>5e-06 7e-06 -4e-06 -0.000705 0.000441 -8.1e-05</velocity>
          <acceleration>-0.006061 0.005588 0.002117 -0.744855 -0.800057 -0.130214</acceleration>
          <wrench>-1.7e-05 1.5e-05 6e-06 0 -0 0</wrench>
        </link>
        <link name='shoulder'>
          <pose frame=''>1.11733 0.861038 0.774429 0.020215 -0.013873 -0.02384</pose>
          <velocity>1e-06 1e-06 0.000117 0.001161 -0.002244 -0</velocity>
          <acceleration>-0.188146 -0.05755 0.216456 1.71809 0.557202 -0.032436</acceleration>
          <wrench>-0.006845 -0.002094 0.007875 0 -0 0</wrench>
        </link>
        <link name='thumb0'>
          <pose frame=''>1.14752 0.282934 0.794267 0.236907 0.010339 -0.292397</pose>
          <velocity>3.1e-05 7.1e-05 1.3e-05 0.000375 -0.001704 -0.002505</velocity>
          <acceleration>0.002569 0.06733 0.038826 -1.77318 -1.55122 0.668247</acceleration>
          <wrench>9e-06 0.000227 0.000131 0 -0 0</wrench>
        </link>
        <link name='thumb1'>
          <pose frame=''>1.16723 0.275795 0.795258 0.19121 0.141417 -0.878425</pose>
          <velocity>9.6e-05 6.5e-05 4.6e-05 0.001244 -0.002292 0.00302</velocity>
          <acceleration>0.170346 0.143616 0.061047 -1.13255 0.875709 1.09546</acceleration>
          <wrench>0.001016 0.000856 0.000364 0 -0 0</wrench>
        </link>
        <link name='thumb2'>
          <pose frame=''>1.18844 0.250436 0.789814 0.191278 0.141486 -0.878418</pose>
          <velocity>0.000134 7e-05 7.2e-05 -0.001349 0.00424 -0.002579</velocity>
          <acceleration>0.109646 0.053509 0.043058 -0.484529 1.44521 -0.04054</acceleration>
          <wrench>0.000658 0.000321 0.000258 0 -0 0</wrench>
        </link>
        <link name='thumb3'>
          <pose frame=''>1.20955 0.224661 0.786146 0.18557 0.148932 -0.917899</pose>
          <velocity>2.2e-05 -1.8e-05 2.3e-05 0.003175 -0.002767 -0.002899</velocity>
          <acceleration>-0.005308 -0.035533 0.014796 1.84211 -0.986726 -1.86267</acceleration>
          <wrench>-1.5e-05 -9.8e-05 4.1e-05 0 -0 0</wrench>
        </link>
        <link name='wristx'>
          <pose frame=''>1.11461 0.332642 0.81002 0.016302 8.1e-05 -0.025515</pose>
          <velocity>2.1e-05 -1.3e-05 4e-06 0.000369 -0.001646 -0.000356</velocity>
          <acceleration>-0.023306 -0.013748 -0.034673 -2.32334 1.36225 2.72852</acceleration>
          <wrench>-0.000249 -0.000147 -0.000371 0 -0 0</wrench>
        </link>
        <link name='wristy'>
          <pose frame=''>1.11569 0.380301 0.808759 0.016309 2e-05 -0.022084</pose>
          <velocity>3.3e-05 -1.4e-05 1.9e-05 0.000372 -0.000637 -0.001098</velocity>
          <acceleration>-0.043716 -0.016712 -0.021436 -2.6544 -0.375187 1.35263</acceleration>
          <wrench>-0.001193 -0.000456 -0.000585 0 -0 0</wrench>
        </link>
        <link name='wristz'>
          <pose frame=''>1.11403 0.302686 0.807438 0.155065 3.7e-05 -0.025507</pose>
          <velocity>9e-06 6e-06 0 -0.000172 0.000201 -2.9e-05</velocity>
          <acceleration>-0.037326 0.010612 -0.026876 -0.347079 -1.25179 -0.089844</acceleration>
          <wrench>-0.004699 0.001336 -0.003383 0 -0 0</wrench>
        </link>
      </model>
      <model name='pan_tilt'>
        <pose frame=''>-0 0 0 0 -0 0</pose>
        <scale>1 1 1</scale>
        <link name='base_link'>
          <pose frame=''>-0 0 0 0 -0 0</pose>
          <velocity>-0 -0 0 0 -0 0</velocity>
          <acceleration>0 -0 -0 0 -0 0</acceleration>
          <wrench>0 -0 -0 0 -0 0</wrench>
        </link>
        <link name='pan_link'>
          <pose frame=''>-0 0 0.315 -0 -0 -2.0316</pose>
          <velocity>-0 -0 -0 0 -0 0.0998</velocity>
          <acceleration>0 -0 0 -3e-06 1e-06 -3e-06</acceleration>
          <wrench>0 -0 0 0 -0 0</wrench>
        </link>
        <link name='tilt_link'>
          <pose frame=''>0.080613 -0.04002 1.815 -3.14159 -1.14159 1.11</pose>
          <velocity>0.003994 0.008045 -0 0 -0 0.0998</velocity>
          <acceleration>-0.000915 0.000223 -0 0.042369 0.008659 -0.007491</acceleration>
          <wrench>-0.005093 0.001242 -0 0 -0 0</wrench>
        </link>
      </model>
      <model name='plastic_cup'>
        <pose frame=''>1.26694 4.0595 0.034139 -1.49594 0.195835 0.027469</pose>
        <scale>1 1 1</scale>
        <link name='link'>
          <pose frame=''>1.26611 4.12432 0.038908 -1.49594 0.195835 0.027469</pose>
          <velocity>0 0 0 0 -0 0</velocity>
          <acceleration>0 -0 -0 0 -0 0</acceleration>
          <wrench>0 -0 -0 0 -0 0</wrench>
        </link>
      </model>
      <model name='plastic_cup_0'>
        <pose frame=''>1.03647 1.30681 0.781938 0.011993 -0.008001 2.09264</pose>
        <scale>1 1 1</scale>
        <link name='link'>
          <pose frame=''>1.03741 1.30675 0.846931 0.011993 -0.008001 2.09264</pose>
          <velocity>0 0 0 0 -0 0</velocity>
          <acceleration>-0.018165 -0.112635 -0.003099 1.55962 -0.251681 0.1695</acceleration>
          <wrench>-0.001088 -0.006747 -0.000186 0 -0 0</wrench>
        </link>
      </model>
      <light name='sun'>
        <pose frame=''>0 0 10 0 -0 0</pose>
      </light>
    </state>
    <gui fullscreen='0'>
      <camera name='user_camera'>
        <pose frame=''>2.48428 7.08887 3.58338 -0 0.473797 -1.61098</pose>
        <view_controller>orbit</view_controller>
        <projection_type>perspective</projection_type>
      </camera>
    </gui>
  </world>
</sdf>
